Workbook

Sheet Fibre Master
A1: Date | B1: Fibre | C1: Origin | D1: Variety | E1: Market Type | F1: Original Price | G1: Original Unit | H1: Currency | I1: Exchange Rate | J1: Standard Price | K1: Standard Unit | L1: Daily Change % | M1: YoY Change % | N1: Year | O1: Month | P1: Source | Q1: Remarks
A2: 46174 | B2: Cotton | C2: India | D2: Indian Cotton | E2: Spot | F2: 63500 | G2: ₹/Candy | H2: INR | I2: =IF(C2="India",1,IF(C2="USA",INDEX('Currency Master'!B:B,MATCH(DATE(N2,MONTH(DATEVALUE(O2&" 1")),1),'Currency Master'!A:A,0)),IF(C2="Australia",INDEX('Currency Master'!T:T,MATCH(DATE(N2,MONTH(DATEVALUE(O2&" 1")),1),'Currency Master'!A:A,0)),""))) -> 1 | J2: =IF(C2="India",F2,IF(C2="USA",IF(G2="US Cents/Lb",ROUND(((F2/100)/0.453592)*I2*356,0),F2),IF(C2="Australia",IF(G2="AUc/kg",ROUND((F2/100)*I2,2),F2),""))) -> 63500 | K2: =IF(C2="India",G2,IF(C2="USA","₹/Candy",IF(C2="Australia","₹/Kg",""))) -> ₹/Candy | L2: -0.066176471 | M2: 0.15454545 | N2: =YEAR(A2) -> 2026 | O2: =TEXT(A2,"mmmm") -> June | P2: Indian Cotton Market
A3: 46143 | B3: Cotton | C3: India | D3: Indian Cotton | E3: Spot | F3: 68000 | G3: ₹/Candy | H3: INR | I3: =IF(C3="India",1,IF(C3="USA",INDEX('Currency Master'!B:B,MATCH(DATE(N3,MONTH(DATEVALUE(O3&" 1")),1),'Currency Master'!A:A,0)),IF(C3="Australia",INDEX('Currency Master'!T:T,MATCH(DATE(N3,MONTH(DATEVALUE(O3&" 1")),1),'Currency Master'!A:A,0)),""))) -> 1 | J3: =IF(C3="India",F3,IF(C3="USA",IF(G3="US Cents/Lb",ROUND(((F3/100)/0.453592)*I3*356,0),F3),IF(C3="Australia",IF(G3="AUc/kg",ROUND((F3/100)*I3,2),F3),""))) -> 68000 | K3: =IF(C3="India",G3,IF(C3="USA","₹/Candy",IF(C3="Australia","₹/Kg",""))) -> ₹/Candy | L3: 0.12026359 | M3: 0.21428571 | N3: =YEAR(A3) -> 2026 | O3: =TEXT(A3,"mmmm") -> May | P3: Indian Cotton Market
A4: 46113 | B4: Cotton | C4: India | D4: Indian Cotton | E4: Spot | F4: 60700 | G4: ₹/Candy | H4: INR | I4: =IF(C4="India",1,IF(C4="USA",INDEX('Currency Master'!B:B,MATCH(DATE(N4,MONTH(DATEVALUE(O4&" 1")),1),'Currency Master'!A:A,0)),IF(C4="Australia",INDEX('Currency Master'!T:T,MATCH(DATE(N4,MONTH(DATEVALUE(O4&" 1")),1),'Currency Master'!A:A,0)),""))) -> 1 | J4: =IF(C4="India",F4,IF(C4="USA",IF(G4="US Cents/Lb",ROUND(((F4/100)/0.453592)*I4*356,0),F4),IF(C4="Australia",IF(G4="AUc/kg",ROUND((F4/100)*I4,2),F4),""))) -> 60700 | K4: =IF(C4="India",G4,IF(C4="USA","₹/Candy",IF(C4="Australia","₹/Kg",""))) -> ₹/Candy | L4: 0.11172161 | M4: 0.10163339 | N4: =YEAR(A4) -> 2026 | O4: =TEXT(A4,"mmmm") -> April | P4: Indian Cotton Market
A5: 46082 | B5: Cotton | C5: India | D5: Indian Cotton | E5: Spot | F5: 54600 | G5: ₹/Candy | H5: INR | I5: =IF(C5="India",1,IF(C5="USA",INDEX('Currency Master'!B:B,MATCH(DATE(N5,MONTH(DATEVALUE(O5&" 1")),1),'Currency Master'!A:A,0)),IF(C5="Australia",INDEX('Currency Master'!T:T,MATCH(DATE(N5,MONTH(DATEVALUE(O5&" 1")),1),'Currency Master'!A:A,0)),""))) -> 1 | J5: =IF(C5="India",F5,IF(C5="USA",IF(G5="US Cents/Lb",ROUND(((F5/100)/0.453592)*I5*356,0),F5),IF(C5="Australia",IF(G5="AUc/kg",ROUND((F5/100)*I5,2),F5),""))) -> 54600 | K5: =IF(C5="India",G5,IF(C5="USA","₹/Candy",IF(C5="Australia","₹/Kg",""))) -> ₹/Candy | L5: 0.0036764706 | M5: 0.011111111 | N5: =YEAR(A5) -> 2026 | O5: =TEXT(A5,"mmmm") -> March | P5: Indian Cotton Market
A6: 46054 | B6: Cotton | C6: India | D6: Indian Cotton | E6: Spot | F6: 54400 | G6: ₹/Candy | H6: INR | I6: =IF(C6="India",1,IF(C6="USA",INDEX('Currency Master'!B:B,MATCH(DATE(N6,MONTH(DATEVALUE(O6&" 1")),1),'Currency Master'!A:A,0)),IF(C6="Australia",INDEX('Currency Master'!T:T,MATCH(DATE(N6,MONTH(DATEVALUE(O6&" 1")),1),'Currency Master'!A:A,0)),""))) -> 1 | J6: =IF(C6="India",F6,IF(C6="USA",IF(G6="US Cents/Lb",ROUND(((F6/100)/0.453592)*I6*356,0),F6),IF(C6="Australia",IF(G6="AUc/kg",ROUND((F6/100)*I6,2),F6),""))) -> 54400 | K6: =IF(C6="India",G6,IF(C6="USA","₹/Candy",IF(C6="Australia","₹/Kg",""))) -> ₹/Candy | L6: 0.0074074074 | M6: 0.013035382 | N6: =YEAR(A6) -> 2026 | O6: =TEXT(A6,"mmmm") -> February | P6: Indian Cotton Market
A7: 46023 | B7: Cotton | C7: India | D7: Indian Cotton | E7: Spot | F7: 54000 | G7: ₹/Candy | H7: INR | I7: =IF(C7="India",1,IF(C7="USA",INDEX('Currency Master'!B:B,MATCH(DATE(N7,MONTH(DATEVALUE(O7&" 1")),1),'Currency Master'!A:A,0)),IF(C7="Australia",INDEX('Currency Master'!T:T,MATCH(DATE(N7,MONTH(DATEVALUE(O7&" 1")),1),'Currency Master'!A:A,0)),""))) -> 1 | J7: =IF(C7="India",F7,IF(C7="USA",IF(G7="US Cents/Lb",ROUND(((F7/100)/0.453592)*I7*356,0),F7),IF(C7="Australia",IF(G7="AUc/kg",ROUND((F7/100)*I7,2),F7),""))) -> 54000 | K7: =IF(C7="India",G7,IF(C7="USA","₹/Candy",IF(C7="Australia","₹/Kg",""))) -> ₹/Candy | L7: 0.03250478 | M7: 0.0055865922 | N7: =YEAR(A7) -> 2026 | O7: =TEXT(A7,"mmmm") -> January | P7: Indian Cotton Market
A8: 45992 | B8: Cotton | C8: India | D8: Indian Cotton | E8: Spot | F8: 52300 | G8: ₹/Candy | H8: INR | I8: =IF(C8="India",1,IF(C8="USA",INDEX('Currency Master'!B:B,MATCH(DATE(N8,MONTH(DATEVALUE(O8&" 1")),1),'Currency Master'!A:A,0)),IF(C8="Australia",INDEX('Currency Master'!T:T,MATCH(DATE(N8,MONTH(DATEVALUE(O8&" 1")),1),'Currency Master'!A:A,0)),""))) -> 1 | J8: =IF(C8="India",F8,IF(C8="USA",IF(G8="US Cents/Lb",ROUND(((F8/100)/0.453592)*I8*356,0),F8),IF(C8="Australia",IF(G8="AUc/kg",ROUND((F8/100)*I8,2),F8),""))) -> 52300 | K8: =IF(C8="India",G8,IF(C8="USA","₹/Candy",IF(C8="Australia","₹/Kg",""))) -> ₹/Candy | L8: 0.0057692308 | M8: -0.036832413 | N8: =YEAR(A8) -> 2025 | O8: =TEXT(A8,"mmmm") -> December | P8: Indian Cotton Market
A9: 45962 | B9: Cotton | C9: India | D9: Indian Cotton | E9: Spot | F9: 52000 | G9: ₹/Candy | H9: INR | I9: =IF(C9="India",1,IF(C9="USA",INDEX('Currency Master'!B:B,MATCH(DATE(N9,MONTH(DATEVALUE(O9&" 1")),1),'Currency Master'!A:A,0)),IF(C9="Australia",INDEX('Currency Master'!T:T,MATCH(DATE(N9,MONTH(DATEVALUE(O9&" 1")),1),'Currency Master'!A:A,0)),""))) -> 1 | J9: =IF(C9="India",F9,IF(C9="USA",IF(G9="US Cents/Lb",ROUND(((F9/100)/0.453592)*I9*356,0),F9),IF(C9="Australia",IF(G9="AUc/kg",ROUND((F9/100)*I9,2),F9),""))) -> 52000 | K9: =IF(C9="India",G9,IF(C9="USA","₹/Candy",IF(C9="Australia","₹/Kg",""))) -> ₹/Candy | L9: -0.026217228 | M9: -0.054545455 | N9: =YEAR(A9) -> 2025 | O9: =TEXT(A9,"mmmm") -> November | P9: Indian Cotton Market
A10: 45931 | B10: Cotton | C10: India | D10: Indian Cotton | E10: Spot | F10: 53400 | G10: ₹/Candy | H10: INR | I10: =IF(C10="India",1,IF(C10="USA",INDEX('Currency Master'!B:B,MATCH(DATE(N10,MONTH(DATEVALUE(O10&" 1")),1),'Currency Master'!A:A,0)),IF(C10="Australia",INDEX('Currency Master'!T:T,MATCH(DATE(N10,MONTH(DATEVALUE(O10&" 1")),1),'Currency Master'!A:A,0)),""))) -> 1 | J10: =IF(C10="India",F10,IF(C10="USA",IF(G10="US Cents/Lb",ROUND(((F10/100)/0.453592)*I10*356,0),F10),IF(C10="Australia",IF(G10="AUc/kg",ROUND((F10/100)*I10,2),F10),""))) -> 53400 | K10: =IF(C10="India",G10,IF(C10="USA","₹/Candy",IF(C10="Australia","₹/Kg",""))) -> ₹/Candy | L10: -0.020183486 | M10: -0.091836735 | N10: =YEAR(A10) -> 2025 | O10: =TEXT(A10,"mmmm") -> October | P10: Indian Cotton Market
A11: 45901 | B11: Cotton | C11: India | D11: Indian Cotton | E11: Spot | F11: 54500 | G11: ₹/Candy | H11: INR | I11: =IF(C11="India",1,IF(C11="USA",INDEX('Currency Master'!B:B,MATCH(DATE(N11,MONTH(DATEVALUE(O11&" 1")),1),'Currency Master'!A:A,0)),IF(C11="Australia",INDEX('Currency Master'!T:T,MATCH(DATE(N11,MONTH(DATEVALUE(O11&" 1")),1),'Currency Master'!A:A,0)),""))) -> 1 | J11: =IF(C11="India",F11,IF(C11="USA",IF(G11="US Cents/Lb",ROUND(((F11/100)/0.453592)*I11*356,0),F11),IF(C11="Australia",IF(G11="AUc/kg",ROUND((F11/100)*I11,2),F11),""))) -> 54500 | K11: =IF(C11="India",G11,IF(C11="USA","₹/Candy",IF(C11="Australia","₹/Kg",""))) -> ₹/Candy | L11: -0.03024911 | M11: -0.079391892 | N11: =YEAR(A11) -> 2025 | O11: =TEXT(A11,"mmmm") -> September | P11: Indian Cotton Market
A12: 45870 | B12: Cotton | C12: India | D12: Indian Cotton | E12: Spot | F12: 56200 | G12: ₹/Candy | H12: INR | I12: =IF(C12="India",1,IF(C12="USA",INDEX('Currency Master'!B:B,MATCH(DATE(N12,MONTH(DATEVALUE(O12&" 1")),1),'Currency Master'!A:A,0)),IF(C12="Australia",INDEX('Currency Master'!T:T,MATCH(DATE(N12,MONTH(DATEVALUE(O12&" 1")),1),'Currency Master'!A:A,0)),""))) -> 1 | J12: =IF(C12="India",F12,IF(C12="USA",IF(G12="US Cents/Lb",ROUND(((F12/100)/0.453592)*I12*356,0),F12),IF(C12="Australia",IF(G12="AUc/kg",ROUND((F12/100)*I12,2),F12),""))) -> 56200 | K12: =IF(C12="India",G12,IF(C12="USA","₹/Candy",IF(C12="Australia","₹/Kg",""))) -> ₹/Candy | L12: 0.016274864 | M12: -0.015761821 | N12: =YEAR(A12) -> 2025 | O12: =TEXT(A12,"mmmm") -> August | P12: Indian Cotton Market
A13: 45839 | B13: Cotton | C13: India | D13: Indian Cotton | E13: Spot | F13: 55300 | G13: ₹/Candy | H13: INR | I13: =IF(C13="India",1,IF(C13="USA",INDEX('Currency Master'!B:B,MATCH(DATE(N13,MONTH(DATEVALUE(O13&" 1")),1),'Currency Master'!A:A,0)),IF(C13="Australia",INDEX('Currency Master'!T:T,MATCH(DATE(N13,MONTH(DATEVALUE(O13&" 1")),1),'Currency Master'!A:A,0)),""))) -> 1 | J13: =IF(C13="India",F13,IF(C13="USA",IF(G13="US Cents/Lb",ROUND(((F13/100)/0.453592)*I13*356,0),F13),IF(C13="Australia",IF(G13="AUc/kg",ROUND((F13/100)*I13,2),F13),""))) -> 55300 | K13: =IF(C13="India",G13,IF(C13="USA","₹/Candy",IF(C13="Australia","₹/Kg",""))) -> ₹/Candy | L13: 0.0054545455 | M13: -0.043252595 | N13: =YEAR(A13) -> 2025 | O13: =TEXT(A13,"mmmm") -> July | P13: Indian Cotton Market
... A247: 38718 | B247: Cotton | C247: India | D247: Indian Cotton | E247: Spot | F247: 20388.12 | G247: ₹/Candy | H247: INR | I247: =IF(C247="India",1,IF(C247="USA",INDEX('Currency Master'!B:B,MATCH(DATE(N247,MONTH(DATEVALUE(O247&" 1")),1),'Currency Master'!A:A,0)),IF(C247="Australia",INDEX('Currency Master'!T:T,MATCH(DATE(N247,MONTH(DATEVALUE(O247&" 1")),1),'Currency Master'!A:A,0)),""))) -> 1 | J247: =IF(C247="India",F247,IF(C247="USA",IF(G247="US Cents/Lb",ROUND(((F247/100)/0.453592)*I247*356,0),F247),IF(C247="Australia",IF(G247="AUc/kg",ROUND((F247/100)*I247,2),F247),""))) -> 20388.12 | K247: =IF(C247="India",G247,IF(C247="USA","₹/Candy",IF(C247="Australia","₹/Kg",""))) -> ₹/Candy | L247: 0.0035044682 | M247: 0.15813953 | N247: =YEAR(A247) -> 2006 | O247: =TEXT(A247,"mmmm") -> January | P247: Indian Cotton Market
A248: 38687 | B248: Cotton | C248: India | D248: Indian Cotton | E248: Spot | F248: 20316.92 | G248: ₹/Candy | H248: INR | I248: =IF(C248="India",1,IF(C248="USA",INDEX('Currency Master'!B:B,MATCH(DATE(N248,MONTH(DATEVALUE(O248&" 1")),1),'Currency Master'!A:A,0)),IF(C248="Australia",INDEX('Currency Master'!T:T,MATCH(DATE(N248,MONTH(DATEVALUE(O248&" 1")),1),'Currency Master'!A:A,0)),""))) -> 1 | J248: =IF(C248="India",F248,IF(C248="USA",IF(G248="US Cents/Lb",ROUND(((F248/100)/0.453592)*I248*356,0),F248),IF(C248="Australia",IF(G248="AUc/kg",ROUND((F248/100)*I248,2),F248),""))) -> 20316.92 | K248: =IF(C248="India",G248,IF(C248="USA","₹/Candy",IF(C248="Australia","₹/Kg",""))) -> ₹/Candy | L248: -0.0015745276 | N248: =YEAR(A248) -> 2005 | O248: =TEXT(A248,"mmmm") -> December | P248: Indian Cotton Market
A249: 38657 | B249: Cotton | C249: India | D249: Indian Cotton | E249: Spot | F249: 20348.96 | G249: ₹/Candy | H249: INR | I249: =IF(C249="India",1,IF(C249="USA",INDEX('Currency Master'!B:B,MATCH(DATE(N249,MONTH(DATEVALUE(O249&" 1")),1),'Currency Master'!A:A,0)),IF(C249="Australia",INDEX('Currency Master'!T:T,MATCH(DATE(N249,MONTH(DATEVALUE(O249&" 1")),1),'Currency Master'!A:A,0)),""))) -> 1 | J249: =IF(C249="India",F249,IF(C249="USA",IF(G249="US Cents/Lb",ROUND(((F249/100)/0.453592)*I249*356,0),F249),IF(C249="Australia",IF(G249="AUc/kg",ROUND((F249/100)*I249,2),F249),""))) -> 20348.96 | K249: =IF(C249="India",G249,IF(C249="USA","₹/Candy",IF(C249="Australia","₹/Kg",""))) -> ₹/Candy | L249: -0.0036604497 | N249: =YEAR(A249) -> 2005 | O249: =TEXT(A249,"mmmm") -> November | P249: Indian Cotton Market
A250: 38626 | B250: Cotton | C250: India | D250: Indian Cotton | E250: Spot | F250: 20423.72 | G250: ₹/Candy | H250: INR | I250: =IF(C250="India",1,IF(C250="USA",INDEX('Currency Master'!B:B,MATCH(DATE(N250,MONTH(DATEVALUE(O250&" 1")),1),'Currency Master'!A:A,0)),IF(C250="Australia",INDEX('Currency Master'!T:T,MATCH(DATE(N250,MONTH(DATEVALUE(O250&" 1")),1),'Currency Master'!A:A,0)),""))) -> 1 | J250: =IF(C250="India",F250,IF(C250="USA",IF(G250="US Cents/Lb",ROUND(((F250/100)/0.453592)*I250*356,0),F250),IF(C250="Australia",IF(G250="AUc/kg",ROUND((F250/100)*I250,2),F250),""))) -> 20423.72 | K250: =IF(C250="India",G250,IF(C250="USA","₹/Candy",IF(C250="Australia","₹/Kg",""))) -> ₹/Candy | L250: 0.079601054 | N250: =YEAR(A250) -> 2005 | O250: =TEXT(A250,"mmmm") -> October | P250: Indian Cotton Market
A251: 38596 | B251: Cotton | C251: India | D251: Indian Cotton | E251: Spot | F251: 18917.84 | G251: ₹/Candy | H251: INR | I251: =IF(C251="India",1,IF(C251="USA",INDEX('Currency Master'!B:B,MATCH(DATE(N251,MONTH(DATEVALUE(O251&" 1")),1),'Currency Master'!A:A,0)),IF(C251="Australia",INDEX('Currency Master'!T:T,MATCH(DATE(N251,MONTH(DATEVALUE(O251&" 1")),1),'Currency Master'!A:A,0)),""))) -> 1 | J251: =IF(C251="India",F251,IF(C251="USA",IF(G251="US Cents/Lb",ROUND(((F251/100)/0.453592)*I251*356,0),F251),IF(C251="Australia",IF(G251="AUc/kg",ROUND((F251/100)*I251,2),F251),""))) -> 18917.84 | K251: =IF(C251="India",G251,IF(C251="USA","₹/Candy",IF(C251="Australia","₹/Kg",""))) -> ₹/Candy | L251: 0.023694856 | N251: =YEAR(A251) -> 2005 | O251: =TEXT(A251,"mmmm") -> September | P251: Indian Cotton Market
A252: 38565 | B252: Cotton | C252: India | D252: Indian Cotton | E252: Spot | F252: 18479.96 | G252: ₹/Candy | H252: INR | I252: =IF(C252="India",1,IF(C252="USA",INDEX('Currency Master'!B:B,MATCH(DATE(N252,MONTH(DATEVALUE(O252&" 1")),1),'Currency Master'!A:A,0)),IF(C252="Australia",INDEX('Currency Master'!T:T,MATCH(DATE(N252,MONTH(DATEVALUE(O252&" 1")),1),'Currency Master'!A:A,0)),""))) -> 1 | J252: =IF(C252="India",F252,IF(C252="USA",IF(G252="US Cents/Lb",ROUND(((F252/100)/0.453592)*I252*356,0),F252),IF(C252="Australia",IF(G252="AUc/kg",ROUND((F252/100)*I252,2),F252),""))) -> 18479.96 | K252: =IF(C252="India",G252,IF(C252="USA","₹/Candy",IF(C252="Australia","₹/Kg",""))) -> ₹/Candy | L252: -0.014616553 | N252: =YEAR(A252) -> 2005 | O252: =TEXT(A252,"mmmm") -> August | P252: Indian Cotton Market
A253: 38534 | B253: Cotton | C253: India | D253: Indian Cotton | E253: Spot | F253: 18754.08 | G253: ₹/Candy | H253: INR | I253: =IF(C253="India",1,IF(C253="USA",INDEX('Currency Master'!B:B,MATCH(DATE(N253,MONTH(DATEVALUE(O253&" 1")),1),'Currency Master'!A:A,0)),IF(C253="Australia",INDEX('Currency Master'!T:T,MATCH(DATE(N253,MONTH(DATEVALUE(O253&" 1")),1),'Currency Master'!A:A,0)),""))) -> 1 | J253: =IF(C253="India",F253,IF(C253="USA",IF(G253="US Cents/Lb",ROUND(((F253/100)/0.453592)*I253*356,0),F253),IF(C253="Australia",IF(G253="AUc/kg",ROUND((F253/100)*I253,2),F253),""))) -> 18754.08 | K253: =IF(C253="India",G253,IF(C253="USA","₹/Candy",IF(C253="Australia","₹/Kg",""))) -> ₹/Candy | L253: 0.015615963 | N253: =YEAR(A253) -> 2005 | O253: =TEXT(A253,"mmmm") -> July | P253: Indian Cotton Market
A254: 38504 | B254: Cotton | C254: India | D254: Indian Cotton | E254: Spot | F254: 18465.72 | G254: ₹/Candy | H254: INR | I254: =IF(C254="India",1,IF(C254="USA",INDEX('Currency Master'!B:B,MATCH(DATE(N254,MONTH(DATEVALUE(O254&" 1")),1),'Currency Master'!A:A,0)),IF(C254="Australia",INDEX('Currency Master'!T:T,MATCH(DATE(N254,MONTH(DATEVALUE(O254&" 1")),1),'Currency Master'!A:A,0)),""))) -> 1 | J254: =IF(C254="India",F254,IF(C254="USA",IF(G254="US Cents/Lb",ROUND(((F254/100)/0.453592)*I254*356,0),F254),IF(C254="Australia",IF(G254="AUc/kg",ROUND((F254/100)*I254,2),F254),""))) -> 18465.72 | K254: =IF(C254="India",G254,IF(C254="USA","₹/Candy",IF(C254="Australia","₹/Kg",""))) -> ₹/Candy | L254: -0.030286035 | N254: =YEAR(A254) -> 2005 | O254: =TEXT(A254,"mmmm") -> June | P254: Indian Cotton Market
A255: 38473 | B255: Cotton | C255: India | D255: Indian Cotton | E255: Spot | F255: 19042.44 | G255: ₹/Candy | H255: INR | I255: =IF(C255="India",1,IF(C255="USA",INDEX('Currency Master'!B:B,MATCH(DATE(N255,MONTH(DATEVALUE(O255&" 1")),1),'Currency Master'!A:A,0)),IF(C255="Australia",INDEX('Currency Master'!T:T,MATCH(DATE(N255,MONTH(DATEVALUE(O255&" 1")),1),'Currency Master'!A:A,0)),""))) -> 1 | J255: =IF(C255="India",F255,IF(C255="USA",IF(G255="US Cents/Lb",ROUND(((F255/100)/0.453592)*I255*356,0),F255),IF(C255="Australia",IF(G255="AUc/kg",ROUND((F255/100)*I255,2),F255),""))) -> 19042.44 | K255: =IF(C255="India",G255,IF(C255="USA","₹/Candy",IF(C255="Australia","₹/Kg",""))) -> ₹/Candy | L255: -0.029395754 | N255: =YEAR(A255) -> 2005 | O255: =TEXT(A255,"mmmm") -> May | P255: Indian Cotton Market
A256: 38443 | B256: Cotton | C256: India | D256: Indian Cotton | E256: Spot | F256: 19619.16 | G256: ₹/Candy | H256: INR | I256: =IF(C256="India",1,IF(C256="USA",INDEX('Currency Master'!B:B,MATCH(DATE(N256,MONTH(DATEVALUE(O256&" 1")),1),'Currency Master'!A:A,0)),IF(C256="Australia",INDEX('Currency Master'!T:T,MATCH(DATE(N256,MONTH(DATEVALUE(O256&" 1")),1),'Currency Master'!A:A,0)),""))) -> 1 | J256: =IF(C256="India",F256,IF(C256="USA",IF(G256="US Cents/Lb",ROUND(((F256/100)/0.453592)*I256*356,0),F256),IF(C256="Australia",IF(G256="AUc/kg",ROUND((F256/100)*I256,2),F256),""))) -> 19619.16 | K256: =IF(C256="India",G256,IF(C256="USA","₹/Candy",IF(C256="Australia","₹/Kg",""))) -> ₹/Candy | L256: 0.017165006 | N256: =YEAR(A256) -> 2005 | O256: =TEXT(A256,"mmmm") -> April | P256: Indian Cotton Market
A257: 38412 | B257: Cotton | C257: India | D257: Indian Cotton | E257: Spot | F257: 19288.08 | G257: ₹/Candy | H257: INR | I257: =IF(C257="India",1,IF(C257="USA",INDEX('Currency Master'!B:B,MATCH(DATE(N257,MONTH(DATEVALUE(O257&" 1")),1),'Currency Master'!A:A,0)),IF(C257="Australia",INDEX('Currency Master'!T:T,MATCH(DATE(N257,MONTH(DATEVALUE(O257&" 1")),1),'Currency Master'!A:A,0)),""))) -> 1 | J257: =IF(C257="India",F257,IF(C257="USA",IF(G257="US Cents/Lb",ROUND(((F257/100)/0.453592)*I257*356,0),F257),IF(C257="Australia",IF(G257="AUc/kg",ROUND((F257/100)*I257,2),F257),""))) -> 19288.08 | K257: =IF(C257="India",G257,IF(C257="USA","₹/Candy",IF(C257="Australia","₹/Kg",""))) -> ₹/Candy | L257: 0.069271758 | N257: =YEAR(A257) -> 2005 | O257: =TEXT(A257,"mmmm") -> March | P257: Indian Cotton Market
A258: 38384 | B258: Cotton | C258: India | D258: Indian Cotton | E258: Spot | F258: 18038.52 | G258: ₹/Candy | H258: INR | I258: =IF(C258="India",1,IF(C258="USA",INDEX('Currency Master'!B:B,MATCH(DATE(N258,MONTH(DATEVALUE(O258&" 1")),1),'Currency Master'!A:A,0)),IF(C258="Australia",INDEX('Currency Master'!T:T,MATCH(DATE(N258,MONTH(DATEVALUE(O258&" 1")),1),'Currency Master'!A:A,0)),""))) -> 1 | J258: =IF(C258="India",F258,IF(C258="USA",IF(G258="US Cents/Lb",ROUND(((F258/100)/0.453592)*I258*356,0),F258),IF(C258="Australia",IF(G258="AUc/kg",ROUND((F258/100)*I258,2),F258),""))) -> 18038.52 | K258: =IF(C258="India",G258,IF(C258="USA","₹/Candy",IF(C258="Australia","₹/Kg",""))) -> ₹/Candy | L258: 0.024671385 | N258: =YEAR(A258) -> 2005 | O258: =TEXT(A258,"mmmm") -> February | P258: Indian Cotton Market
A259: 38353 | B259: Cotton | C259: India | D259: Indian Cotton | E259: Spot | F259: 17604.2 | G259: ₹/Candy | H259: INR | I259: =IF(C259="India",1,IF(C259="USA",INDEX('Currency Master'!B:B,MATCH(DATE(N259,MONTH(DATEVALUE(O259&" 1")),1),'Currency Master'!A:A,0)),IF(C259="Australia",INDEX('Currency Master'!T:T,MATCH(DATE(N259,MONTH(DATEVALUE(O259&" 1")),1),'Currency Master'!A:A,0)),""))) -> 1 | J259: =IF(C259="India",F259,IF(C259="USA",IF(G259="US Cents/Lb",ROUND(((F259/100)/0.453592)*I259*356,0),F259),IF(C259="Australia",IF(G259="AUc/kg",ROUND((F259/100)*I259,2),F259),""))) -> 17604.2 | K259: =IF(C259="India",G259,IF(C259="USA","₹/Candy",IF(C259="Australia","₹/Kg",""))) -> ₹/Candy | N259: =YEAR(A259) -> 2005 | O259: =TEXT(A259,"mmmm") -> January | P259: Indian Cotton Market
A260: 46143 | B260: Cotton | C260: USA | D260: US Cotton | E260: Import/CIF | F260: 76315.72 | G260: ₹/Candy | H260: INR | I260: =IF(C260="India",1,IF(C260="USA",INDEX('Currency Master'!B:B,MATCH(DATE(N260,MONTH(DATEVALUE(O260&" 1")),1),'Currency Master'!A:A,0)),IF(C260="Australia",INDEX('Currency Master'!T:T,MATCH(DATE(N260,MONTH(DATEVALUE(O260&" 1")),1),'Currency Master'!A:A,0)),""))) -> 94.34 | J260: =IF(C260="India",F260,IF(C260="USA",IF(G260="US Cents/Lb",ROUND(((F260/100)/0.453592)*I260*356,0),F260),IF(C260="Australia",IF(G260="AUc/kg",ROUND((F260/100)*I260,2),F260),""))) -> 76315.72 | K260: =IF(C260="India",G260,IF(C260="USA","₹/Candy",IF(C260="Australia","₹/Kg",""))) -> ₹/Candy | L260: 0.3006993 | N260: =YEAR(A260) -> 2026 | O260: =TEXT(A260,"mmmm") -> May | P260: US Cotton Market
A261: 46113 | B261: Cotton | C261: USA | D261: US Cotton | E261: Import/CIF | F261: 60201.263 | G261: ₹/Candy | H261: INR | I261: =IF(C261="India",1,IF(C261="USA",INDEX('Currency Master'!B:B,MATCH(DATE(N261,MONTH(DATEVALUE(O261&" 1")),1),'Currency Master'!A:A,0)),IF(C261="Australia",INDEX('Currency Master'!T:T,MATCH(DATE(N261,MONTH(DATEVALUE(O261&" 1")),1),'Currency Master'!A:A,0)),""))) -> 92.91 | J261: =IF(C261="India",F261,IF(C261="USA",IF(G261="US Cents/Lb",ROUND(((F261/100)/0.453592)*I261*356,0),F261),IF(C261="Australia",IF(G261="AUc/kg",ROUND((F261/100)*I261,2),F261),""))) -> 60201.263 | K261: =IF(C261="India",G261,IF(C261="USA","₹/Candy",IF(C261="Australia","₹/Kg",""))) -> ₹/Candy | L261: 0.014184397 | N261: =YEAR(A261) -> 2026 | O261: =TEXT(A261,"mmmm") -> April | P261: US Cotton Market
A262: 46082 | B262: Cotton | C262: USA | D262: US Cotton | E262: Import/CIF | F262: 58608.547 | G262: ₹/Candy | H262: INR | I262: =IF(C262="India",1,IF(C262="USA",INDEX('Currency Master'!B:B,MATCH(DATE(N262,MONTH(DATEVALUE(O262&" 1")),1),'Currency Master'!A:A,0)),IF(C262="Australia",INDEX('Currency Master'!T:T,MATCH(DATE(N262,MONTH(DATEVALUE(O262&" 1")),1),'Currency Master'!A:A,0)),""))) -> 91.477 | J262: =IF(C262="India",F262,IF(C262="USA",IF(G262="US Cents/Lb",ROUND(((F262/100)/0.453592)*I262*356,0),F262),IF(C262="Australia",IF(G262="AUc/kg",ROUND((F262/100)*I262,2),F262),""))) -> 58608.547 | K262: =IF(C262="India",G262,IF(C262="USA","₹/Candy",IF(C262="Australia","₹/Kg",""))) -> ₹/Candy | L262: 0.02173913 | N262: =YEAR(A262) -> 2026 | O262: =TEXT(A262,"mmmm") -> March | P262: US Cotton Market
A263: 46054 | B263: Cotton | C263: USA | D263: US Cotton | E263: Import/CIF | F263: 55897.226 | G263: ₹/Candy | H263: INR | I263: =IF(C263="India",1,IF(C263="USA",INDEX('Currency Master'!B:B,MATCH(DATE(N263,MONTH(DATEVALUE(O263&" 1")),1),'Currency Master'!A:A,0)),IF(C263="Australia",INDEX('Currency Master'!T:T,MATCH(DATE(N263,MONTH(DATEVALUE(O263&" 1")),1),'Currency Master'!A:A,0)),""))) -> 91.66 | J263: =IF(C263="India",F263,IF(C263="USA",IF(G263="US Cents/Lb",ROUND(((F263/100)/0.453592)*I263*356,0),F263),IF(C263="Australia",IF(G263="AUc/kg",ROUND((F263/100)*I263,2),F263),""))) -> 55897.226 | K263: =IF(C263="India",G263,IF(C263="USA","₹/Candy",IF(C263="Australia","₹/Kg",""))) -> ₹/Candy | L263: -0.028169014 | N263: =YEAR(A263) -> 2026 | O263: =TEXT(A263,"mmmm") -> February | P263: US Cotton Market
A264: 46023 | B264: Cotton | C264: USA | D264: US Cotton | E264: Import/CIF | F264: 57311.059 | G264: ₹/Candy | H264: INR | I264: =IF(C264="India",1,IF(C264="USA",INDEX('Currency Master'!B:B,MATCH(DATE(N264,MONTH(DATEVALUE(O264&" 1")),1),'Currency Master'!A:A,0)),IF(C264="Australia",INDEX('Currency Master'!T:T,MATCH(DATE(N264,MONTH(DATEVALUE(O264&" 1")),1),'Currency Master'!A:A,0)),""))) -> 89.96 | J264: =IF(C264="India",F264,IF(C264="USA",IF(G264="US Cents/Lb",ROUND(((F264/100)/0.453592)*I264*356,0),F264),IF(C264="Australia",IF(G264="AUc/kg",ROUND((F264/100)*I264,2),F264),""))) -> 57311.059 | K264: =IF(C264="India",G264,IF(C264="USA","₹/Candy",IF(C264="Australia","₹/Kg",""))) -> ₹/Candy | L264: 0.0070921986 | N264: =YEAR(A264) -> 2026 | O264: =TEXT(A264,"mmmm") -> January | P264: US Cotton Market
A265: 45992 | B265: Cotton | C265: USA | D265: US Cotton | E265: Import/CIF | F265: 56957.601 | G265: ₹/Candy | H265: INR | I265: =IF(C265="India",1,IF(C265="USA",INDEX('Currency Master'!B:B,MATCH(DATE(N265,MONTH(DATEVALUE(O265&" 1")),1),'Currency Master'!A:A,0)),IF(C265="Australia",INDEX('Currency Master'!T:T,MATCH(DATE(N265,MONTH(DATEVALUE(O265&" 1")),1),'Currency Master'!A:A,0)),""))) -> 90.07 | J265: =IF(C265="India",F265,IF(C265="USA",IF(G265="US Cents/Lb",ROUND(((F265/100)/0.453592)*I265*356,0),F265),IF(C265="Australia",IF(G265="AUc/kg",ROUND((F265/100)*I265,2),F265),""))) -> 56957.601 | K265: =IF(C265="India",G265,IF(C265="USA","₹/Candy",IF(C265="Australia","₹/Kg",""))) -> ₹/Candy | L265: -0.034246575 | N265: =YEAR(A265) -> 2025 | O265: =TEXT(A265,"mmmm") -> December | P265: US Cotton Market
A266: 45962 | B266: Cotton | C266: USA | D266: US Cotton | E266: Import/CIF | F266: 57867.287 | G266: ₹/Candy | H266: INR | I266: =IF(C266="India",1,IF(C266="USA",INDEX('Currency Master'!B:B,MATCH(DATE(N266,MONTH(DATEVALUE(O266&" 1")),1),'Currency Master'!A:A,0)),IF(C266="Australia",INDEX('Currency Master'!T:T,MATCH(DATE(N266,MONTH(DATEVALUE(O266&" 1")),1),'Currency Master'!A:A,0)),""))) -> 88.76 | J266: =IF(C266="India",F266,IF(C266="USA",IF(G266="US Cents/Lb",ROUND(((F266/100)/0.453592)*I266*356,0),F266),IF(C266="Australia",IF(G266="AUc/kg",ROUND((F266/100)*I266,2),F266),""))) -> 57867.287 | K266: =IF(C266="India",G266,IF(C266="USA","₹/Candy",IF(C266="Australia","₹/Kg",""))) -> ₹/Candy | L266: 0.035460993 | N266: =YEAR(A266) -> 2025 | O266: =TEXT(A266,"mmmm") -> November | P266: US Cotton Market
A267: 45931 | B267: Cotton | C267: USA | D267: US Cotton | E267: Import/CIF | F267: 56123.293 | G267: ₹/Candy | H267: INR | I267: =IF(C267="India",1,IF(C267="USA",INDEX('Currency Master'!B:B,MATCH(DATE(N267,MONTH(DATEVALUE(O267&" 1")),1),'Currency Master'!A:A,0)),IF(C267="Australia",INDEX('Currency Master'!T:T,MATCH(DATE(N267,MONTH(DATEVALUE(O267&" 1")),1),'Currency Master'!A:A,0)),""))) -> 88.749 | J267: =IF(C267="India",F267,IF(C267="USA",IF(G267="US Cents/Lb",ROUND(((F267/100)/0.453592)*I267*356,0),F267),IF(C267="Australia",IF(G267="AUc/kg",ROUND((F267/100)*I267,2),F267),""))) -> 56123.293 | K267: =IF(C267="India",G267,IF(C267="USA","₹/Candy",IF(C267="Australia","₹/Kg",""))) -> ₹/Candy | L267: -0.013986014 | N267: =YEAR(A267) -> 2025 | O267: =TEXT(A267,"mmmm") -> October | P267: US Cotton Market
A268: 45901 | B268: Cotton | C268: USA | D268: US Cotton | E268: Import/CIF | F268: 56435.343 | G268: ₹/Candy | H268: INR | I268: =IF(C268="India",1,IF(C268="USA",INDEX('Currency Master'!B:B,MATCH(DATE(N268,MONTH(DATEVALUE(O268&" 1")),1),'Currency Master'!A:A,0)),IF(C268="Australia",INDEX('Currency Master'!T:T,MATCH(DATE(N268,MONTH(DATEVALUE(O268&" 1")),1),'Currency Master'!A:A,0)),""))) -> 88.065 | J268: =IF(C268="India",F268,IF(C268="USA",IF(G268="US Cents/Lb",ROUND(((F268/100)/0.453592)*I268*356,0),F268),IF(C268="Australia",IF(G268="AUc/kg",ROUND((F268/100)*I268,2),F268),""))) -> 56435.343 | K268: =IF(C268="India",G268,IF(C268="USA","₹/Candy",IF(C268="Australia","₹/Kg",""))) -> ₹/Candy | L268: -0.020547945 | N268: =YEAR(A268) -> 2025 | O268: =TEXT(A268,"mmmm") -> September | P268: US Cotton Market
A269: 45870 | B269: Cotton | C269: USA | D269: US Cotton | E269: Import/CIF | F269: 56952.51 | G269: ₹/Candy | H269: INR | I269: =IF(C269="India",1,IF(C269="USA",INDEX('Currency Master'!B:B,MATCH(DATE(N269,MONTH(DATEVALUE(O269&" 1")),1),'Currency Master'!A:A,0)),IF(C269="Australia",INDEX('Currency Master'!T:T,MATCH(DATE(N269,MONTH(DATEVALUE(O269&" 1")),1),'Currency Master'!A:A,0)),""))) -> 87.16 | J269: =IF(C269="India",F269,IF(C269="USA",IF(G269="US Cents/Lb",ROUND(((F269/100)/0.453592)*I269*356,0),F269),IF(C269="Australia",IF(G269="AUc/kg",ROUND((F269/100)*I269,2),F269),""))) -> 56952.51 | K269: =IF(C269="India",G269,IF(C269="USA","₹/Candy",IF(C269="Australia","₹/Kg",""))) -> ₹/Candy | L269: -0.026666667 | N269: =YEAR(A269) -> 2025 | O269: =TEXT(A269,"mmmm") -> August | P269: US Cotton Market
A270: 45839 | B270: Cotton | C270: USA | D270: US Cotton | E270: Import/CIF | F270: 57154.732 | G270: ₹/Candy | H270: INR | I270: =IF(C270="India",1,IF(C270="USA",INDEX('Currency Master'!B:B,MATCH(DATE(N270,MONTH(DATEVALUE(O270&" 1")),1),'Currency Master'!A:A,0)),IF(C270="Australia",INDEX('Currency Master'!T:T,MATCH(DATE(N270,MONTH(DATEVALUE(O270&" 1")),1),'Currency Master'!A:A,0)),""))) -> 85.18 | J270: =IF(C270="India",F270,IF(C270="USA",IF(G270="US Cents/Lb",ROUND(((F270/100)/0.453592)*I270*356,0),F270),IF(C270="Australia",IF(G270="AUc/kg",ROUND((F270/100)*I270,2),F270),""))) -> 57154.732 | K270: =IF(C270="India",G270,IF(C270="USA","₹/Candy",IF(C270="Australia","₹/Kg",""))) -> ₹/Candy | L270: -0.13294798 | N270: =YEAR(A270) -> 2025 | O270: =TEXT(A270,"mmmm") -> July | P270: US Cotton Market
A271: 45809 | B271: Cotton | C271: USA | D271: US Cotton | E271: Import/CIF | F271: 64955.443 | G271: ₹/Candy | H271: INR | I271: =IF(C271="India",1,IF(C271="USA",INDEX('Currency Master'!B:B,MATCH(DATE(N271,MONTH(DATEVALUE(O271&" 1")),1),'Currency Master'!A:A,0)),IF(C271="Australia",INDEX('Currency Master'!T:T,MATCH(DATE(N271,MONTH(DATEVALUE(O271&" 1")),1),'Currency Master'!A:A,0)),""))) -> 85.37 | J271: =IF(C271="India",F271,IF(C271="USA",IF(G271="US Cents/Lb",ROUND(((F271/100)/0.453592)*I271*356,0),F271),IF(C271="Australia",IF(G271="AUc/kg",ROUND((F271/100)*I271,2),F271),""))) -> 64955.443 | K271: =IF(C271="India",G271,IF(C271="USA","₹/Candy",IF(C271="Australia","₹/Kg",""))) -> ₹/Candy | L271: 0.0058139535 | N271: =YEAR(A271) -> 2025 | O271: =TEXT(A271,"mmmm") -> June | P271: US Cotton Market
... A663: 33878 | B663: Cotton | C663: USA | D663: US Cotton | E663: Import/CIF | F663: 20893.567 | G663: ₹/Candy | H663: INR | I663: =IF(C663="India",1,IF(C663="USA",INDEX('Currency Master'!B:B,MATCH(DATE(N663,MONTH(DATEVALUE(O663&" 1")),1),'Currency Master'!A:A,0)),IF(C663="Australia",INDEX('Currency Master'!T:T,MATCH(DATE(N663,MONTH(DATEVALUE(O663&" 1")),1),'Currency Master'!A:A,0)),""))) -> 28.473904 | J663: =IF(C663="India",F663,IF(C663="USA",IF(G663="US Cents/Lb",ROUND(((F663/100)/0.453592)*I663*356,0),F663),IF(C663="Australia",IF(G663="AUc/kg",ROUND((F663/100)*I663,2),F663),""))) -> 20893.567 | K663: =IF(C663="India",G663,IF(C663="USA","₹/Candy",IF(C663="Australia","₹/Kg",""))) -> ₹/Candy | L663: -0.064 | N663: =YEAR(A663) -> 1992 | O663: =TEXT(A663,"mmmm") -> October | P663: US Cotton Market
A664: 33848 | B664: Cotton | C664: USA | D664: US Cotton | E664: Import/CIF | F664: 21828.496 | G664: ₹/Candy | H664: INR | I664: =IF(C664="India",1,IF(C664="USA",INDEX('Currency Master'!B:B,MATCH(DATE(N664,MONTH(DATEVALUE(O664&" 1")),1),'Currency Master'!A:A,0)),IF(C664="Australia",INDEX('Currency Master'!T:T,MATCH(DATE(N664,MONTH(DATEVALUE(O664&" 1")),1),'Currency Master'!A:A,0)),""))) -> 28.454554 | J664: =IF(C664="India",F664,IF(C664="USA",IF(G664="US Cents/Lb",ROUND(((F664/100)/0.453592)*I664*356,0),F664),IF(C664="Australia",IF(G664="AUc/kg",ROUND((F664/100)*I664,2),F664),""))) -> 21828.496 | K664: =IF(C664="India",G664,IF(C664="USA","₹/Candy",IF(C664="Australia","₹/Kg",""))) -> ₹/Candy | L664: - | N664: =YEAR(A664) -> 1992 | O664: =TEXT(A664,"mmmm") -> September | P664: US Cotton Market
...

Sheet Supima
A1: Report Time | B1: Value | C1: Unit | D1: % Change | E1: Index | F1: Subproduct/Geography | G1: Color/Leaf | H1: Staple | J1: Report Time | K1: Value | L1: Unit | M1: % Change | N1: Index | O1: Subproduct/Geography | P1: Color/Leaf | Q1: Staple
A2: 45292 | B2: 1.84 | C2: USD/Pound | D2: 0 | E2: Supima | F2: American Pima | G2: 2/2 | H2: 46 | J2: 45292 | K2: 1.7325 | L2: USD/Pound | M2: 0 | N2: Supima | O2: American Pima | P2: 3/3 | Q2: 46
A3: 45261 | B3: 1.84 | C3: USD/Pound | D3: 0 | E3: Supima | F3: American Pima | G3: 2/2 | H3: 46 | J3: 45261 | K3: 1.7325 | L3: USD/Pound | M3: 0 | N3: Supima | O3: American Pima | P3: 3/3 | Q3: 46
A4: 45231 | B4: 1.84 | C4: USD/Pound | D4: 0 | E4: Supima | F4: American Pima | G4: 2/2 | H4: 46 | J4: 45231 | K4: 1.7325 | L4: USD/Pound | M4: 0 | N4: Supima | O4: American Pima | P4: 3/3 | Q4: 46
A5: 45200 | B5: 1.84 | C5: USD/Pound | D5: 0 | E5: Supima | F5: American Pima | G5: 2/2 | H5: 46 | J5: 45200 | K5: 1.7325 | L5: USD/Pound | M5: 0 | N5: Supima | O5: American Pima | P5: 3/3 | Q5: 46
A6: 45170 | B6: 1.84 | C6: USD/Pound | D6: 0 | E6: Supima | F6: American Pima | G6: 2/2 | H6: 46 | J6: 45170 | K6: 1.7325 | L6: USD/Pound | M6: 0 | N6: Supima | O6: American Pima | P6: 3/3 | Q6: 46
A7: 45139 | B7: 1.84 | C7: USD/Pound | D7: 5.1428571 | E7: Supima | F7: American Pima | G7: 2/2 | H7: 46 | J7: 45139 | K7: 1.7325 | L7: USD/Pound | M7: 5.4878049 | N7: Supima | O7: American Pima | P7: 3/3 | Q7: 46
A8: 45108 | B8: 1.7465 | C8: USD/Pound | D8: 4.7904192 | E8: Supima | F8: American Pima | G8: 2/2 | H8: 46 | J8: 45108 | K8: 1.639 | L8: USD/Pound | M8: 5.1282051 | N8: Supima | O8: American Pima | P8: 3/3 | Q8: 46
A9: 45078 | B9: 1.67 | C9: USD/Pound | D9: 0 | E9: Supima | F9: American Pima | G9: 2/2 | H9: 46 | J9: 45078 | K9: 1.5625 | L9: USD/Pound | M9: 0 | N9: Supima | O9: American Pima | P9: 3/3 | Q9: 46
A10: 45047 | B10: 1.67 | C10: USD/Pound | D10: -1.183432 | E10: Supima | F10: American Pima | G10: 2/2 | H10: 46 | J10: 45047 | K10: 1.5625 | L10: USD/Pound | M10: -1.2658228 | N10: Supima | O10: American Pima | P10: 3/3 | Q10: 46
A11: 45017 | B11: 1.6866667 | C11: USD/Pound | D11: -15.5 | E11: Supima | F11: American Pima | G11: 2/2 | H11: 46 | J11: 45017 | K11: 1.5791667 | L11: USD/Pound | M11: -16.402116 | N11: Supima | O11: American Pima | P11: 3/3 | Q11: 46
A12: 44986 | B12: 2.0021739 | C12: USD/Pound | D12: -10.714286 | E12: Supima | F12: American Pima | G12: 2/2 | H12: 46 | J12: 44986 | K12: 1.8946739 | L12: USD/Pound | M12: -11.267606 | N12: Supima | O12: American Pima | P12: 3/3 | Q12: 46
A13: 44958 | B13: 2.2421053 | C13: USD/Pound | D13: -15.789474 | E13: Supima | F13: American Pima | G13: 2/2 | H13: 46 | J13: 44958 | K13: 2.1346053 | L13: USD/Pound | M13: -16.796875 | N13: Supima | O13: American Pima | P13: 3/3 | Q13: 46
... A60: 43525 | B60: 1.2 | C60: USD/Pound | D60: 0 | E60: Supima | F60: American Pima | G60: 2/2 | H60: 46 | J60: 43525 | K60: 1.0525 | L60: USD/Pound | M60: 0 | N60: Supima | O60: American Pima | P60: 3/3 | Q60: 46

Sheet Currency Master
A1: Month-Year | B1: USD/INR | C1: USD/CNY | D1: USD/VND | E1: USD/BDT | F1: USD/HKD | G1: USD/TRY | H1: USD/LKR | I1: USD/SGD | J1: USD/MYR | K1: USD/AE | L1: USD/IDR | M1: USD/JP | N1: USD/THB | O1: USD/MU | P1: USD/TW | Q1: USD/IR | R1: USD/GBP | S1: USD/EUR | T1: AUD/INR | U1: EUR/INR | V1: GBP/INR
A2: 46143 | B2: 94.34 | C2: 6.77 | D2: 26300 | E2: 122.64 | F2: 7.82 | G2: 43.97 | H2: 308.74 | I2: 1.26 | J2: 3.96 | K2: 3.6728 | L2: 16803 | M2: 155.07 | N2: 31.85 | O2: 46.07 | P2: 31.14 | Q2: 42112 | R2: 0.075 | S2: 0.86 | T2: 59.7 | U2: 104.71 | V2: 119.99
A3: 46113 | B3: 92.91 | C3: 6.81 | D3: 26045 | E3: 122.2 | F3: 7.81 | G3: 42.57 | H3: 307.05 | I3: 1.27 | J3: 3.92 | K3: 3.6728 | L3: 16758 | M3: 155.2 | N3: 32.37 | O3: 44.49 | P3: 30.78 | Q3: 42000 | R3: 0.7601 | S3: 0.862 | T3: 57.8 | U3: 102.65 | V3: 116.63
A4: 46082 | B4: 91.477 | C4: 6.87 | D4: 25970 | E4: 120.91 | F4: 7.79 | G4: 42.57 | H4: 306.74 | I4: 1.29 | J4: 4.05 | K4: 3.6728 | L4: 16657 | M4: 156.73 | N4: 32.39 | O4: 44.85 | P4: 30.44 | Q4: 42025 | R4: 0.745 | S4: 0.8541 | T4: 58.35 | U4: 105.27 | V4: 119.59
A5: 46054 | B5: 91.66 | C5: 6.95 | D5: 25950 | E5: 120.72 | F5: 7.78 | G5: 42.57 | H5: 308.31 | I5: 1.3 | J5: 4.11 | K5: 3.6728 | L5: 16679 | M5: 154.99 | N5: 32.28 | O5: 44.85 | P5: 30.74 | Q5: 42025 | R5: 0.7381 | S5: 0.8594 | T5: 57.36 | U5: 103.84 | V5: 119.06
A6: 46023 | B6: 89.96 | C6: 6.99 | D6: 26290 | E6: 122.29 | F6: 7.77 | G6: 42.01 | H6: 300.58 | I6: 1.3 | J6: 4.2 | K6: 3.6728 | L6: 16630 | M6: 153.99 | N6: 32.35 | O6: 45.15 | P6: 29.83 | Q6: 42000 | R6: 0.7543 | S6: 0.8749 | T6: 56.54 | U6: 100.51 | V6: 116.85
A7: 45992 | B7: 90.07 | C7: 7 | D7: 26309 | E7: 120.31 | F7: 7.78 | G7: 41.59 | H7: 299.28 | I7: 1.29 | J7: 4.21 | K7: 3.6728 | L7: 16644.1 | M7: 147.08 | N7: 32.44 | O7: 43.8 | P7: 28.97 | Q7: 42000 | R7: 0.73 | S7: 0.851 | T7: 55.94 | U7: 100.64 | V7: 116.6
A8: 45962 | B8: 88.76 | C8: 7.17 | D8: 26405 | E8: 120.17 | F8: 7.8 | G8: 41.14 | H8: 298.79 | I8: 1.28 | J8: 4.22 | K8: 3.6728 | L8: 16405.2 | M8: 147.08 | N8: 32.87 | O8: 45.7 | P8: 29.9 | Q8: 42000 | R8: 0.74 | S8: 0.88 | T8: 54.79 | U8: 97.96 | V8: 115.19
A9: 45931 | B9: 88.749 | C9: 7.12 | D9: 26340 | E9: 120 | F9: 7.85 | G9: 40.63 | H9: 298.14 | I9: 1.29 | J9: 4.28 | K9: 3.6728 | L9: 16358.2 | M9: 147.38 | N9: 33.51 | O9: 43.83 | P9: 32.11 | Q9: 42000 | R9: 0.75 | S9: 0.89 | T9: 54.37 | U9: 97.06 | V9: 112.13
A10: 45901 | B10: 88.065 | C10: 7.13 | D10: 26190 | E10: 120.63 | F10: 7.85 | G10: 39.84 | H10: 297.14 | I10: 1.27 | J10: 4.2 | K10: 3.6728 | L10: 16185 | M10: 143.4 | N10: 34.18 | O10: 44.5 | P10: 33.26 | Q10: 42000 | R10: 0.77 | S10: 0.93 | T10: 51.66 | U10: 92.73 | V10: 110.6
A11: 45870 | B11: 87.16 | C11: 7.21 | D11: 26110 | E11: 120.45 | F11: 7.84 | G11: 39.26 | H11: 298.41 | I11: 1.29 | J11: 4.26 | K11: 3.6728 | L11: 16304 | M11: 143.46 | N11: 34.2 | O11: 45.5 | P11: 32.9 | Q11: 42000 | R11: 0.79 | S11: 0.96 | T11: 54.22 | U11: 90.83 | V11: 109.99
A12: 45839 | B12: 85.18 | C12: 7.16 | D12: 26024 | E12: 121.73 | F12: 7.75 | G12: 38.5 | H12: 300 | I12: 1.31 | J12: 4.31 | K12: 3.6728 | L12: 16601 | M12: 145.45 | N12: 33.73 | O12: 46.5 | P12: 32.736 | Q12: 42000 | R12: 0.79 | S12: 0.9561 | T12: 54.08 | U12: 89.9 | V12: 108.14
A13: 45809 | B13: 85.37 | C13: 7.21 | D13: 26002 | E13: 121.61 | F13: 7.78 | G13: 37.9 | H13: 295.9 | I13: 1.3 | J13: 4.43 | K13: 3.6728 | L13: 16457 | M13: 147.87 | N13: 33.66 | O13: 46.5 | P13: 32.969 | Q13: 42000 | R13: 0.8 | S13: 0.97 | T13: 53 | U13: 88.18 | V13: 107.82
... A323: 36373 | B323: 43.503182 | C323: 8.277 | D323: 13948 | E323: 49.5 | F323: 7.7582 | G323: 0.473097 | H323: 71.55 | I323: 1.7005 | J323: 3.8 | K323: 3.6729 | L323: 6705 | M323: 121.04 | N323: 37.556522 | O323: 25.07 | P323: 33.145 | Q323: 1755 | R323: 0.6203 | S323: 0.918917 | T323: 26.916 | U323: 46.270107 | V323: 68.304
A324: 36342 | B324: 43.362646 | C324: 8.2774 | D324: 13932.5 | E324: 48.5 | F324: 7.7547 | H324: 70.85 | I324: 1.727 | J324: 3.7997 | K324: 3.673 | L324: 8115 | M324: 121.52 | N324: 37.128486 | O324: 24.945 | P324: 33.08 | Q324: 1755 | R324: 0.6243 | S324: 0.89236 | T324: 26.409 | U324: 47.672705 | V324: 68.394
A325: 36312 | B325: 43.212727 | C325: 8.2787 | D325: 13912.5 | E325: 48.5 | F325: 7.7513 | H325: 69.625 | I325: 1.6965 | J325: 3.8 | K325: 3.6728 | L325: 8017.5 | M325: 119.49 | N325: 36.614479 | O325: 24.85 | P325: 32.315 | Q325: 1755 | R325: 0.6081 | S325: 0.861346 | T325: 26.792 | U325: 49.396774 | V325: 69.928
A326: 36281 | B326: 42.878331 | C326: 8.2784 | D326: 13908.5 | E326: 48.475 | F326: 7.7495 | H326: 69.425 | I326: 1.727 | J326: 3.7999 | K326: 3.6729 | L326: 8650 | M326: 118.86 | N326: 36.283478 | O326: 24.73 | P326: 32.22 | Q326: 1754 | R326: 0.6028 | S326: 0.853966 | T326: 26.013 | U326: 49.876115 | V326: 70.251
A327: 36251 | B327: 42.796818 | C327: 8.279 | D327: 13902 | E327: 48.5 | F327: 7.7475 | H327: 69.53 | I327: 1.722 | J327: 3.8 | K327: 3.673 | L327: 8800 | M327: 119.17 | N327: 36.544824 | O327: 24.785 | P327: 32.445 | Q327: 1754 | R327: 0.6062 | S327: 0.859614 | T327: 26.751 | U327: 49.361962 | V327: 70.145
A328: 36220 | B328: 42.516087 | C328: 8.28 | D328: 13892 | E328: 48.4 | F328: 7.7488 | H328: 68.825 | I328: 1.6912 | J328: 3.7999 | K328: 3.6729 | L328: 8850 | M328: 116.32 | N328: 38.147215 | O328: 24.775 | P328: 32.425 | Q328: 1754 | R328: 0.597 | S328: 0.837804 | T328: 26.428 | U328: 50.626664 | V328: 70.976
A329: 36192 | B329: 42.536137 | C329: 8.279 | D329: 13880 | E329: 48.45 | F329: 7.7471 | H329: 68.43 | I329: 1.651 | J329: 3.8 | K329: 3.6729 | L329: 8000 | M329: 113.69 | N329: 40.399891 | O329: 24.585 | P329: 34.45 | Q329: 1754 | R329: 0.5886 | S329: 0.869513 | T329: 25.176 | U329: 48.956381 | V329: 72.065
A330: 36161 | B330: 42.544345 | C330: 8.2778 | D330: 13893 | E330: 48.5 | F330: 7.7425 | H330: 67.9 | I330: 1.6485 | J330: 3.8 | K330: 3.6729 | L330: 7437.5 | M330: 122.95 | N330: 41.72 | O330: 24.475 | P330: 34.855 | Q330: 1754 | R330: 0.5979 | S330: 0.913006 | T330: 24.165 | U330: 46.926551 | V330: 71.548
A331: 36130 | B331: 42.591304 | C331: 8.2789 | D331: 13885 | E331: 48.5 | F331: 7.7445 | H331: 67.075 | I331: 1.6235 | J331: 3.8 | K331: 3.673 | L331: 7600 | M331: 115.79 | N331: 41.299565 | O331: 24.2 | P331: 34.365 | Q331: 1754 | R331: 0.6117 | S331: 0.91768 | T331: 25.787 | U331: 46.438185 | V331: 69.529
A332: 36100 | B332: 42.428359 | C332: 8.2782 | D332: 13906 | E332: 48.5 | F332: 7.749 | H332: 65.985 | I332: 1.6875 | J332: 3.805 | K332: 3.673 | L332: 10700 | M332: 136.48 | N332: 42.331818 | O332: 24.25 | P332: 34.361 | Q332: 1754 | R332: 0.5998 | S332: 0.914278 | T332: 26.32 | U332: 46.33956 | V332: 70.723
A333: 36069 | B333: 42.41255 | C333: 8.2778 | D333: 13904 | E333: 47.1 | F333: 7.7497 | H333: 66.525 | I333: 1.7615 | J333: 4.1653 | K333: 3.673 | L333: 11050 | M333: 139.12 | N333: 39.212715 | O333: 23.915 | P333: 33.975 | Q333: 1754 | R333: 0.6132 | S333: 0.906782 | T333: 25.946 | U333: 44.644871 | V333: 67.91
A334: 36039 | B334: 42.558654 | C334: 8.278 | D334: 13907.5 | E334: 47.1 | F334: 7.7495 | H334: 65.925 | I334: 1.7285 | J334: 4.1502 | K334: 3.6729 | L334: 13150 | M334: 144.53 | N334: 39.653636 | O334: 23.8 | P334: 32.974 | Q334: 1754 | R334: 0.5983 | S334: 0.926072 | T334: 25.785 | U334: 42.87845 | V334: 66.364
A335: 36008 | B335: 42.842857 | C335: 8.28 | D335: 12994 | E335: 47.1 | F335: 7.747 | H335: 65.4 | I335: 1.6865 | J335: 4.13 | K335: 3.673 | L335: 14800 | M335: 138.86 | N335: 41.365909 | O335: 24 | P335: 32.875 | Q335: 1754 | R335: 0.5975 | S335: 0.931539 | T335: 26.166 | U335: 42.477567 | V335: 66.086
... A348: 35612 | B348: 35.746968 | C348: 8.2903 | D348: 11667.5 | E348: 43.65 | F348: 7.7485 | H348: 58.305 | I348: 1.4305 | J348: 2.514 | K348: 3.672 | L348: 2433.5 | M348: 116.23 | N348: 25.970073 | O348: 20.075 | P348: 27.52 | Q348: 1747.5 | R348: 0.6139 | S348: 0.856468 | T348: 27.912 | U348: 41.919179 | V348: 58.434
A349: 35582 | B349: 35.82019 | C349: 8.2907 | D349: 11660 | E349: 43.65 | F349: 7.7462 | H349: 59.2 | I349: 1.4475 | J349: 2.511 | K349: 3.672 | L349: 2430 | M349: 127.09 | N349: 25.732989 | O349: 19.955 | P349: 27.43 | R349: 0.6241 | S349: 0.817998 | T349: 27.33 | U349: 43.934578 | V349: 57.45
A350: 35551 | B350: 35.817919 | C350: 8.2921 | D350: 11656 | E350: 43.65 | F350: 7.7489 | H350: 58.33 | I350: 1.445 | J350: 2.479 | K350: 3.6723 | L350: 2401 | M350: 123.94 | N350: 25.6 | O350: 19.83 | P350: 27.5 | R350: 0.5841 | S350: 0.794113 | T350: 28.495 | U350: 45.183504 | V350: 61.411
A351: 35521 | B351: 35.828136 | C351: 8.2945 | D351: 11650.5 | E351: 43.2 | F351: 7.7435 | H351: 57.5 | I351: 1.425 | J351: 2.4815 | K351: 3.6729 | L351: 2396.5 | M351: 120.42 | N351: 25.462848 | O351: 20.115 | P351: 27.489 | R351: 0.5949 | S351: 0.775522 | T351: 29.162 | U351: 46.23024 | V351: 60.084
A352: 35490 | B352: 35.884762 | C352: 8.2955 | D352: 11204.5 | E352: 42.75 | F352: 7.7492 | H352: 57.69 | I352: 1.4085 | J352: 2.4858 | K352: 3.6725 | L352: 2376.5 | M352: 121.36 | N352: 25.474465 | O352: 20.4 | P352: 27.54 | R352: 0.6144 | S352: 0.784003 | T352: 28.255 | U352: 45.665306 | V352: 58.089
A353: 35462 | B353: 35.89885 | C353: 8.2954 | D353: 11182.5 | E353: 42.45 | F353: 7.7345 | H353: 56.73 | I353: 1.3995 | J353: 2.5255 | K353: 3.672 | L353: 2362 | M353: 115.89 | N353: 25.402294 | O353: 20.61 | P353: 27.48 | R353: 0.6392 | S353: 0.775252 | T353: 28.219 | U353: 46.269317 | V353: 55.805
A354: 35431 | B354: 35.922632 | C354: 8.2934 | D354: 11150.5 | E354: 42.45 | F354: 7.732 | H354: 56.63 | I354: 1.4025 | J354: 2.527 | K354: 3.6728 | L354: 2345 | M354: 113.96 | N354: 25.289091 | O354: 20.245 | P354: 27.471 | R354: 0.6401 | S354: 0.765263 | T354: 28.148 | U354: 46.781759 | V354: 55.687
A355: 35400 | B355: 35.880091 | C355: 8.2984 | D355: 11094.5 | E355: 42.45 | F355: 7.7323 | H355: 57.05 | I355: 1.4095 | J355: 2.527 | K355: 3.6725 | L355: 2329.3 | M355: 114.04 | N355: 25.352163 | O355: 20.05 | P355: 27.518 | R355: 0.6428 | S355: 0.773985 | T355: 27.471 | U355: 46.054588 | V355: 55.335
A356: 35370 | B356: 35.851078 | C356: 8.3012 | D356: 11065 | E356: 43.649826 | F356: 7.7327 | H356: 56.6 | I356: 1.4076 | J356: 2.5062 | K356: 3.673 | L356: 2322.8 | M356: 110.84 | N356: 25.354 | O356: 20.015 | P356: 27.52 | R356: 0.6439 | S356: 0.785362 | T356: 27.543 | U356: 44.693018 | V356: 54.267
A357: 35339 | B357: 35.800515 | C357: 8.3 | D357: 11030.5 | E357: 43.284039 | F357: 7.7325 | H357: 55.6 | I357: 1.4065 | J357: 2.4935 | K357: 3.6732 | L357: 2342 | M357: 108.91 | N357: 25.29087 | O357: 19.55 | P357: 27.677 | R357: 0.6451 | S357: 0.788358 | T357: 27.913 | U357: 44.44086 | V357: 54.209
A358: 35309 | B358: 35.86825 | C358: 8.3017 | D358: 11019.5 | E358: 42.806512 | F358: 7.7335 | H358: 55.12 | I358: 1.4131 | J358: 2.4952 | K358: 3.6728 | L358: 2352.5 | M358: 106.84 | N358: 25.29 | O358: 19.415 | P358: 27.174 | R358: 0.6653 | S358: 0.775367 | T358: 27.279 | U358: 44.265254 | V358: 52.198
A359: 35278 | B359: 35.8 | C359: 8.3063 | D359: 11020 | E359: 43.233562 | F359: 7.741 | H359: 55.505 | I359: 1.4115 | J359: 2.495 | K359: 3.6727 | L359: 2326.5 | M359: 109.74 | N359: 25.250476 | O359: 18.935 | P359: 27.27 | R359: 0.6552 | S359: 0.765195 | T359: 26.677 | U359: 45.067786 | V359: 52.054
A360: 35247 | B360: 35.636952 | C360: 8.3107 | D360: 11014 | E360: 43.8402 | F360: 7.7367 | H360: 54.95 | I360: 1.408 | J360: 2.496 | K360: 3.6727 | L360: 2332.5 | M360: 108.11 | N360: 25.234651 | O360: 18.685 | P360: 27.498 | R360: 0.6531 | S360: 0.7609 | T360: 26.508 | U360: 48.062869 | V360: 53.126
... A369: 34973 | B369: 34.619969 | C369: 8.3149 | D369: 11022.5 | E369: 38.449467 | F369: 7.741 | H369: 51.65 | I369: 1.4205 | J369: 2.4935 | K369: 3.673 | L369: 2266.5 | M369: 97.47 | N369: 24.663801 | O369: 17.395 | P369: 25.576 | R369: 0.629 | S369: 0.743333 | T369: 22.568 | U369: 42.287891 | V369: 49.868
...

Sheet China Cotton
A1: Date | B1: Price | C1: Change %
A2: 45992 | B2: 13720 | C2: -0.0029
A3: 45962 | B3: 13760 | C3: 0.0125
A4: 45931 | B4: 13590 | C4: 0.026
A5: 45901 | B5: 13245 | C5: -0.0553
A6: 45870 | B6: 14020 | C6: 0.0297
A7: 45839 | B7: 13615 | C7: -0.0087
A8: 45809 | B8: 13735 | C8: 0.035
A9: 45778 | B9: 13270 | C9: 0.0387
A10: 45748 | B10: 12775 | C10: -0.0593
A11: 45717 | B11: 13580 | C11: -0.0015
A12: 45689 | B12: 13600 | C12: -0.0029
A13: 45658 | B13: 13640 | C13: 0.0134
... A209: 39692 | B209: 12975 | C209: 0.005
