Workbook

Sheet Yarn_Master
A1: Date | B1: Yarn Category | C1: Material | D1: Origin | E1: Supplier / Mill | F1: Count | G1: Variant | H1: Blend / Composition | I1: Original Price | J1: Original Unit | K1: Currency | L1: Exchange Rate | M1: Standard Price | N1: Standard Unit | O1: Price Basis | P1: GST Included | Q1: Source | R1: Remarks | S1: Year | T1: Month
A2: 44743 | B2: ='yarn master raw '!B2 -> Cotton Yarn | C2: ='yarn master raw '!C2 -> Cotton | D2: =IF('yarn master raw '!J2="INR","India","Imported") -> India | E2: ='yarn master raw '!D2 -> KPR | F2: ='yarn master raw '!E2 -> 16's | G2: ='yarn master raw '!F2 -> Semi-Combed | H2: ='yarn master raw '!G2 -> 100% Cotton | I2: ='yarn master raw '!I2 -> 364 | J2: ='yarn master raw '!H2 -> ₹/kg | K2: ='yarn master raw '!J2 -> INR | L2: =_xlfn.XLOOKUP(K2,'usd inr forecast '!$N$2:$N$6,'usd inr forecast '!$O$2:$O$6,1) -> 1 | M2: =IF(J2="₹/kg",I2*L2,IF(J2="₹/Candy",I2*L2/355.62,IF(J2="₹/Bale",I2*L2/170,I2*L2))) -> 364 | N2: ="₹/kg" -> ₹/kg | O2: ='yarn master raw '!K2 -> Ex-Mill + Freight | P2: ='yarn master raw '!L2 -> No | Q2: ='yarn master raw '!M2 -> Cotton Yarn Price Trend | R2: ='yarn master raw '!N2 -> Historical Price | S2: =IFERROR(IF(ISNUMBER(A2),YEAR(A2),IF(ISNUMBER(SEARCH("'",A2)),VALUE("20"&MID(A2,SEARCH("'",A2)+1,2)),IF(ISNUMBER(SEARCH("2023",A2)),2023,IF(ISNUMBER(SEARCH("2024",A2)),2024,IF(ISNUMBER(SEARCH("2025",A2)),2025,IF(ISNUMBER(SEARCH("2026",A2)),2026,2022)))))),"") -> 2022 | T2: =IFERROR(IF(ISNUMBER(A2),TEXT(A2,"mmmm"),IF(ISNUMBER(SEARCH("Jan",A2)),"January",IF(ISNUMBER(SEARCH("Feb",A2)),"February",IF(ISNUMBER(SEARCH("March",A2)),"March",IF(ISNUMBER(SEARCH("April",A2)),"April",IF(ISNUMBER(SEARCH("May",A2)),"May",IF(ISNUMBER(SEARCH("June",A2)),"June",IF(ISNUMBER(SEARCH("July",A2)),"July",IF(ISNUMBER(SEARCH("Aug",A2)),"August",IF(ISNUMBER(SEARCH("Sep",A2)),"September",IF(ISNUMBER(SEARCH("Oct",A2)),"October",IF(ISNUMBER(SEARCH("Nov",A2)),"November",IF(ISNUMBER(SEARCH("Dec",A2)),"December",""))))))))))))),"") -> July
A3: 44743 | B3: ='yarn master raw '!B3 -> Cotton Yarn | C3: ='yarn master raw '!C3 -> Cotton | D3: =IF('yarn master raw '!J3="INR","India","Imported") -> India | E3: ='yarn master raw '!D3 -> KPR | F3: ='yarn master raw '!E3 -> 20's | G3: ='yarn master raw '!F3 -> Semi-Combed | H3: ='yarn master raw '!G3 -> 100% Cotton | I3: ='yarn master raw '!I3 -> 367 | J3: ='yarn master raw '!H3 -> ₹/kg | K3: ='yarn master raw '!J3 -> INR | L3: =_xlfn.XLOOKUP(K3,'usd inr forecast '!$N$2:$N$6,'usd inr forecast '!$O$2:$O$6,1) -> 1 | M3: =IF(J3="₹/kg",I3*L3,IF(J3="₹/Candy",I3*L3/355.62,IF(J3="₹/Bale",I3*L3/170,I3*L3))) -> 367 | N3: ="₹/kg" -> ₹/kg | O3: ='yarn master raw '!K3 -> Ex-Mill + Freight | P3: ='yarn master raw '!L3 -> No | Q3: ='yarn master raw '!M3 -> Cotton Yarn Price Trend | R3: ='yarn master raw '!N3 -> Historical Price | S3: =IFERROR(IF(ISNUMBER(A3),YEAR(A3),IF(ISNUMBER(SEARCH("'",A3)),VALUE("20"&MID(A3,SEARCH("'",A3)+1,2)),IF(ISNUMBER(SEARCH("2023",A3)),2023,IF(ISNUMBER(SEARCH("2024",A3)),2024,IF(ISNUMBER(SEARCH("2025",A3)),2025,IF(ISNUMBER(SEARCH("2026",A3)),2026,2022)))))),"") -> 2022 | T3: =IFERROR(IF(ISNUMBER(A3),TEXT(A3,"mmmm"),IF(ISNUMBER(SEARCH("Jan",A3)),"January",IF(ISNUMBER(SEARCH("Feb",A3)),"February",IF(ISNUMBER(SEARCH("March",A3)),"March",IF(ISNUMBER(SEARCH("April",A3)),"April",IF(ISNUMBER(SEARCH("May",A3)),"May",IF(ISNUMBER(SEARCH("June",A3)),"June",IF(ISNUMBER(SEARCH("July",A3)),"July",IF(ISNUMBER(SEARCH("Aug",A3)),"August",IF(ISNUMBER(SEARCH("Sep",A3)),"September",IF(ISNUMBER(SEARCH("Oct",A3)),"October",IF(ISNUMBER(SEARCH("Nov",A3)),"November",IF(ISNUMBER(SEARCH("Dec",A3)),"December",""))))))))))))),"") -> July
A4: 44743 | B4: ='yarn master raw '!B4 -> Cotton Yarn | C4: ='yarn master raw '!C4 -> Cotton | D4: =IF('yarn master raw '!J4="INR","India","Imported") -> India | E4: ='yarn master raw '!D4 -> KPR | F4: ='yarn master raw '!E4 -> 24's | G4: ='yarn master raw '!F4 -> Semi-Combed | H4: ='yarn master raw '!G4 -> 100% Cotton | I4: ='yarn master raw '!I4 -> 376 | J4: ='yarn master raw '!H4 -> ₹/kg | K4: ='yarn master raw '!J4 -> INR | L4: =_xlfn.XLOOKUP(K4,'usd inr forecast '!$N$2:$N$6,'usd inr forecast '!$O$2:$O$6,1) -> 1 | M4: =IF(J4="₹/kg",I4*L4,IF(J4="₹/Candy",I4*L4/355.62,IF(J4="₹/Bale",I4*L4/170,I4*L4))) -> 376 | N4: ="₹/kg" -> ₹/kg | O4: ='yarn master raw '!K4 -> Ex-Mill + Freight | P4: ='yarn master raw '!L4 -> No | Q4: ='yarn master raw '!M4 -> Cotton Yarn Price Trend | R4: ='yarn master raw '!N4 -> Historical Price | S4: =IFERROR(IF(ISNUMBER(A4),YEAR(A4),IF(ISNUMBER(SEARCH("'",A4)),VALUE("20"&MID(A4,SEARCH("'",A4)+1,2)),IF(ISNUMBER(SEARCH("2023",A4)),2023,IF(ISNUMBER(SEARCH("2024",A4)),2024,IF(ISNUMBER(SEARCH("2025",A4)),2025,IF(ISNUMBER(SEARCH("2026",A4)),2026,2022)))))),"") -> 2022 | T4: =IFERROR(IF(ISNUMBER(A4),TEXT(A4,"mmmm"),IF(ISNUMBER(SEARCH("Jan",A4)),"January",IF(ISNUMBER(SEARCH("Feb",A4)),"February",IF(ISNUMBER(SEARCH("March",A4)),"March",IF(ISNUMBER(SEARCH("April",A4)),"April",IF(ISNUMBER(SEARCH("May",A4)),"May",IF(ISNUMBER(SEARCH("June",A4)),"June",IF(ISNUMBER(SEARCH("July",A4)),"July",IF(ISNUMBER(SEARCH("Aug",A4)),"August",IF(ISNUMBER(SEARCH("Sep",A4)),"September",IF(ISNUMBER(SEARCH("Oct",A4)),"October",IF(ISNUMBER(SEARCH("Nov",A4)),"November",IF(ISNUMBER(SEARCH("Dec",A4)),"December",""))))))))))))),"") -> July
A5: 44743 | B5: ='yarn master raw '!B5 -> Cotton Yarn | C5: ='yarn master raw '!C5 -> Cotton | D5: =IF('yarn master raw '!J5="INR","India","Imported") -> India | E5: ='yarn master raw '!D5 -> KPR | F5: ='yarn master raw '!E5 -> 30's | G5: ='yarn master raw '!F5 -> Semi-Combed | H5: ='yarn master raw '!G5 -> 100% Cotton | I5: ='yarn master raw '!I5 -> 388 | J5: ='yarn master raw '!H5 -> ₹/kg | K5: ='yarn master raw '!J5 -> INR | L5: =_xlfn.XLOOKUP(K5,'usd inr forecast '!$N$2:$N$6,'usd inr forecast '!$O$2:$O$6,1) -> 1 | M5: =IF(J5="₹/kg",I5*L5,IF(J5="₹/Candy",I5*L5/355.62,IF(J5="₹/Bale",I5*L5/170,I5*L5))) -> 388 | N5: ="₹/kg" -> ₹/kg | O5: ='yarn master raw '!K5 -> Ex-Mill + Freight | P5: ='yarn master raw '!L5 -> No | Q5: ='yarn master raw '!M5 -> Cotton Yarn Price Trend | R5: ='yarn master raw '!N5 -> Historical Price | S5: =IFERROR(IF(ISNUMBER(A5),YEAR(A5),IF(ISNUMBER(SEARCH("'",A5)),VALUE("20"&MID(A5,SEARCH("'",A5)+1,2)),IF(ISNUMBER(SEARCH("2023",A5)),2023,IF(ISNUMBER(SEARCH("2024",A5)),2024,IF(ISNUMBER(SEARCH("2025",A5)),2025,IF(ISNUMBER(SEARCH("2026",A5)),2026,2022)))))),"") -> 2022 | T5: =IFERROR(IF(ISNUMBER(A5),TEXT(A5,"mmmm"),IF(ISNUMBER(SEARCH("Jan",A5)),"January",IF(ISNUMBER(SEARCH("Feb",A5)),"February",IF(ISNUMBER(SEARCH("March",A5)),"March",IF(ISNUMBER(SEARCH("April",A5)),"April",IF(ISNUMBER(SEARCH("May",A5)),"May",IF(ISNUMBER(SEARCH("June",A5)),"June",IF(ISNUMBER(SEARCH("July",A5)),"July",IF(ISNUMBER(SEARCH("Aug",A5)),"August",IF(ISNUMBER(SEARCH("Sep",A5)),"September",IF(ISNUMBER(SEARCH("Oct",A5)),"October",IF(ISNUMBER(SEARCH("Nov",A5)),"November",IF(ISNUMBER(SEARCH("Dec",A5)),"December",""))))))))))))),"") -> July
A6: 44743 | B6: ='yarn master raw '!B6 -> Cotton Yarn | C6: ='yarn master raw '!C6 -> Cotton | D6: =IF('yarn master raw '!J6="INR","India","Imported") -> India | E6: ='yarn master raw '!D6 -> KPR | F6: ='yarn master raw '!E6 -> 34's | G6: ='yarn master raw '!F6 -> Semi-Combed | H6: ='yarn master raw '!G6 -> 100% Cotton | I6: ='yarn master raw '!I6 -> 402 | J6: ='yarn master raw '!H6 -> ₹/kg | K6: ='yarn master raw '!J6 -> INR | L6: =_xlfn.XLOOKUP(K6,'usd inr forecast '!$N$2:$N$6,'usd inr forecast '!$O$2:$O$6,1) -> 1 | M6: =IF(J6="₹/kg",I6*L6,IF(J6="₹/Candy",I6*L6/355.62,IF(J6="₹/Bale",I6*L6/170,I6*L6))) -> 402 | N6: ="₹/kg" -> ₹/kg | O6: ='yarn master raw '!K6 -> Ex-Mill + Freight | P6: ='yarn master raw '!L6 -> No | Q6: ='yarn master raw '!M6 -> Cotton Yarn Price Trend | R6: ='yarn master raw '!N6 -> Historical Price | S6: =IFERROR(IF(ISNUMBER(A6),YEAR(A6),IF(ISNUMBER(SEARCH("'",A6)),VALUE("20"&MID(A6,SEARCH("'",A6)+1,2)),IF(ISNUMBER(SEARCH("2023",A6)),2023,IF(ISNUMBER(SEARCH("2024",A6)),2024,IF(ISNUMBER(SEARCH("2025",A6)),2025,IF(ISNUMBER(SEARCH("2026",A6)),2026,2022)))))),"") -> 2022 | T6: =IFERROR(IF(ISNUMBER(A6),TEXT(A6,"mmmm"),IF(ISNUMBER(SEARCH("Jan",A6)),"January",IF(ISNUMBER(SEARCH("Feb",A6)),"February",IF(ISNUMBER(SEARCH("March",A6)),"March",IF(ISNUMBER(SEARCH("April",A6)),"April",IF(ISNUMBER(SEARCH("May",A6)),"May",IF(ISNUMBER(SEARCH("June",A6)),"June",IF(ISNUMBER(SEARCH("July",A6)),"July",IF(ISNUMBER(SEARCH("Aug",A6)),"August",IF(ISNUMBER(SEARCH("Sep",A6)),"September",IF(ISNUMBER(SEARCH("Oct",A6)),"October",IF(ISNUMBER(SEARCH("Nov",A6)),"November",IF(ISNUMBER(SEARCH("Dec",A6)),"December",""))))))))))))),"") -> July
A7: 44743 | B7: ='yarn master raw '!B7 -> Cotton Yarn | C7: ='yarn master raw '!C7 -> Cotton | D7: =IF('yarn master raw '!J7="INR","India","Imported") -> India | E7: ='yarn master raw '!D7 -> KPR | F7: ='yarn master raw '!E7 -> 40's | G7: ='yarn master raw '!F7 -> Semi-Combed | H7: ='yarn master raw '!G7 -> 100% Cotton | I7: ='yarn master raw '!I7 -> 423 | J7: ='yarn master raw '!H7 -> ₹/kg | K7: ='yarn master raw '!J7 -> INR | L7: =_xlfn.XLOOKUP(K7,'usd inr forecast '!$N$2:$N$6,'usd inr forecast '!$O$2:$O$6,1) -> 1 | M7: =IF(J7="₹/kg",I7*L7,IF(J7="₹/Candy",I7*L7/355.62,IF(J7="₹/Bale",I7*L7/170,I7*L7))) -> 423 | N7: ="₹/kg" -> ₹/kg | O7: ='yarn master raw '!K7 -> Ex-Mill + Freight | P7: ='yarn master raw '!L7 -> No | Q7: ='yarn master raw '!M7 -> Cotton Yarn Price Trend | R7: ='yarn master raw '!N7 -> Historical Price | S7: =IFERROR(IF(ISNUMBER(A7),YEAR(A7),IF(ISNUMBER(SEARCH("'",A7)),VALUE("20"&MID(A7,SEARCH("'",A7)+1,2)),IF(ISNUMBER(SEARCH("2023",A7)),2023,IF(ISNUMBER(SEARCH("2024",A7)),2024,IF(ISNUMBER(SEARCH("2025",A7)),2025,IF(ISNUMBER(SEARCH("2026",A7)),2026,2022)))))),"") -> 2022 | T7: =IFERROR(IF(ISNUMBER(A7),TEXT(A7,"mmmm"),IF(ISNUMBER(SEARCH("Jan",A7)),"January",IF(ISNUMBER(SEARCH("Feb",A7)),"February",IF(ISNUMBER(SEARCH("March",A7)),"March",IF(ISNUMBER(SEARCH("April",A7)),"April",IF(ISNUMBER(SEARCH("May",A7)),"May",IF(ISNUMBER(SEARCH("June",A7)),"June",IF(ISNUMBER(SEARCH("July",A7)),"July",IF(ISNUMBER(SEARCH("Aug",A7)),"August",IF(ISNUMBER(SEARCH("Sep",A7)),"September",IF(ISNUMBER(SEARCH("Oct",A7)),"October",IF(ISNUMBER(SEARCH("Nov",A7)),"November",IF(ISNUMBER(SEARCH("Dec",A7)),"December",""))))))))))))),"") -> July
A8: 44774 | B8: ='yarn master raw '!B8 -> Cotton Yarn | C8: ='yarn master raw '!C8 -> Cotton | D8: =IF('yarn master raw '!J8="INR","India","Imported") -> India | E8: ='yarn master raw '!D8 -> KPR | F8: ='yarn master raw '!E8 -> 16's | G8: ='yarn master raw '!F8 -> Semi-Combed | H8: ='yarn master raw '!G8 -> 100% Cotton | I8: ='yarn master raw '!I8 -> 334 | J8: ='yarn master raw '!H8 -> ₹/kg | K8: ='yarn master raw '!J8 -> INR | L8: =_xlfn.XLOOKUP(K8,'usd inr forecast '!$N$2:$N$6,'usd inr forecast '!$O$2:$O$6,1) -> 1 | M8: =IF(J8="₹/kg",I8*L8,IF(J8="₹/Candy",I8*L8/355.62,IF(J8="₹/Bale",I8*L8/170,I8*L8))) -> 334 | N8: ="₹/kg" -> ₹/kg | O8: ='yarn master raw '!K8 -> Ex-Mill + Freight | P8: ='yarn master raw '!L8 -> No | Q8: ='yarn master raw '!M8 -> Cotton Yarn Price Trend | R8: ='yarn master raw '!N8 -> Historical Price | S8: =IFERROR(IF(ISNUMBER(A8),YEAR(A8),IF(ISNUMBER(SEARCH("'",A8)),VALUE("20"&MID(A8,SEARCH("'",A8)+1,2)),IF(ISNUMBER(SEARCH("2023",A8)),2023,IF(ISNUMBER(SEARCH("2024",A8)),2024,IF(ISNUMBER(SEARCH("2025",A8)),2025,IF(ISNUMBER(SEARCH("2026",A8)),2026,2022)))))),"") -> 2022 | T8: =IFERROR(IF(ISNUMBER(A8),TEXT(A8,"mmmm"),IF(ISNUMBER(SEARCH("Jan",A8)),"January",IF(ISNUMBER(SEARCH("Feb",A8)),"February",IF(ISNUMBER(SEARCH("March",A8)),"March",IF(ISNUMBER(SEARCH("April",A8)),"April",IF(ISNUMBER(SEARCH("May",A8)),"May",IF(ISNUMBER(SEARCH("June",A8)),"June",IF(ISNUMBER(SEARCH("July",A8)),"July",IF(ISNUMBER(SEARCH("Aug",A8)),"August",IF(ISNUMBER(SEARCH("Sep",A8)),"September",IF(ISNUMBER(SEARCH("Oct",A8)),"October",IF(ISNUMBER(SEARCH("Nov",A8)),"November",IF(ISNUMBER(SEARCH("Dec",A8)),"December",""))))))))))))),"") -> August
A9: 44774 | B9: ='yarn master raw '!B9 -> Cotton Yarn | C9: ='yarn master raw '!C9 -> Cotton | D9: =IF('yarn master raw '!J9="INR","India","Imported") -> India | E9: ='yarn master raw '!D9 -> KPR | F9: ='yarn master raw '!E9 -> 20's | G9: ='yarn master raw '!F9 -> Semi-Combed | H9: ='yarn master raw '!G9 -> 100% Cotton | I9: ='yarn master raw '!I9 -> 337 | J9: ='yarn master raw '!H9 -> ₹/kg | K9: ='yarn master raw '!J9 -> INR | L9: =_xlfn.XLOOKUP(K9,'usd inr forecast '!$N$2:$N$6,'usd inr forecast '!$O$2:$O$6,1) -> 1 | M9: =IF(J9="₹/kg",I9*L9,IF(J9="₹/Candy",I9*L9/355.62,IF(J9="₹/Bale",I9*L9/170,I9*L9))) -> 337 | N9: ="₹/kg" -> ₹/kg | O9: ='yarn master raw '!K9 -> Ex-Mill + Freight | P9: ='yarn master raw '!L9 -> No | Q9: ='yarn master raw '!M9 -> Cotton Yarn Price Trend | R9: ='yarn master raw '!N9 -> Historical Price | S9: =IFERROR(IF(ISNUMBER(A9),YEAR(A9),IF(ISNUMBER(SEARCH("'",A9)),VALUE("20"&MID(A9,SEARCH("'",A9)+1,2)),IF(ISNUMBER(SEARCH("2023",A9)),2023,IF(ISNUMBER(SEARCH("2024",A9)),2024,IF(ISNUMBER(SEARCH("2025",A9)),2025,IF(ISNUMBER(SEARCH("2026",A9)),2026,2022)))))),"") -> 2022 | T9: =IFERROR(IF(ISNUMBER(A9),TEXT(A9,"mmmm"),IF(ISNUMBER(SEARCH("Jan",A9)),"January",IF(ISNUMBER(SEARCH("Feb",A9)),"February",IF(ISNUMBER(SEARCH("March",A9)),"March",IF(ISNUMBER(SEARCH("April",A9)),"April",IF(ISNUMBER(SEARCH("May",A9)),"May",IF(ISNUMBER(SEARCH("June",A9)),"June",IF(ISNUMBER(SEARCH("July",A9)),"July",IF(ISNUMBER(SEARCH("Aug",A9)),"August",IF(ISNUMBER(SEARCH("Sep",A9)),"September",IF(ISNUMBER(SEARCH("Oct",A9)),"October",IF(ISNUMBER(SEARCH("Nov",A9)),"November",IF(ISNUMBER(SEARCH("Dec",A9)),"December",""))))))))))))),"") -> August
A10: 44774 | B10: ='yarn master raw '!B10 -> Cotton Yarn | C10: ='yarn master raw '!C10 -> Cotton | D10: =IF('yarn master raw '!J10="INR","India","Imported") -> India | E10: ='yarn master raw '!D10 -> KPR | F10: ='yarn master raw '!E10 -> 24's | G10: ='yarn master raw '!F10 -> Semi-Combed | H10: ='yarn master raw '!G10 -> 100% Cotton | I10: ='yarn master raw '!I10 -> 346 | J10: ='yarn master raw '!H10 -> ₹/kg | K10: ='yarn master raw '!J10 -> INR | L10: =_xlfn.XLOOKUP(K10,'usd inr forecast '!$N$2:$N$6,'usd inr forecast '!$O$2:$O$6,1) -> 1 | M10: =IF(J10="₹/kg",I10*L10,IF(J10="₹/Candy",I10*L10/355.62,IF(J10="₹/Bale",I10*L10/170,I10*L10))) -> 346 | N10: ="₹/kg" -> ₹/kg | O10: ='yarn master raw '!K10 -> Ex-Mill + Freight | P10: ='yarn master raw '!L10 -> No | Q10: ='yarn master raw '!M10 -> Cotton Yarn Price Trend | R10: ='yarn master raw '!N10 -> Historical Price | S10: =IFERROR(IF(ISNUMBER(A10),YEAR(A10),IF(ISNUMBER(SEARCH("'",A10)),VALUE("20"&MID(A10,SEARCH("'",A10)+1,2)),IF(ISNUMBER(SEARCH("2023",A10)),2023,IF(ISNUMBER(SEARCH("2024",A10)),2024,IF(ISNUMBER(SEARCH("2025",A10)),2025,IF(ISNUMBER(SEARCH("2026",A10)),2026,2022)))))),"") -> 2022 | T10: =IFERROR(IF(ISNUMBER(A10),TEXT(A10,"mmmm"),IF(ISNUMBER(SEARCH("Jan",A10)),"January",IF(ISNUMBER(SEARCH("Feb",A10)),"February",IF(ISNUMBER(SEARCH("March",A10)),"March",IF(ISNUMBER(SEARCH("April",A10)),"April",IF(ISNUMBER(SEARCH("May",A10)),"May",IF(ISNUMBER(SEARCH("June",A10)),"June",IF(ISNUMBER(SEARCH("July",A10)),"July",IF(ISNUMBER(SEARCH("Aug",A10)),"August",IF(ISNUMBER(SEARCH("Sep",A10)),"September",IF(ISNUMBER(SEARCH("Oct",A10)),"October",IF(ISNUMBER(SEARCH("Nov",A10)),"November",IF(ISNUMBER(SEARCH("Dec",A10)),"December",""))))))))))))),"") -> August
A11: 44774 | B11: ='yarn master raw '!B11 -> Cotton Yarn | C11: ='yarn master raw '!C11 -> Cotton | D11: =IF('yarn master raw '!J11="INR","India","Imported") -> India | E11: ='yarn master raw '!D11 -> KPR | F11: ='yarn master raw '!E11 -> 30's | G11: ='yarn master raw '!F11 -> Semi-Combed | H11: ='yarn master raw '!G11 -> 100% Cotton | I11: ='yarn master raw '!I11 -> 358 | J11: ='yarn master raw '!H11 -> ₹/kg | K11: ='yarn master raw '!J11 -> INR | L11: =_xlfn.XLOOKUP(K11,'usd inr forecast '!$N$2:$N$6,'usd inr forecast '!$O$2:$O$6,1) -> 1 | M11: =IF(J11="₹/kg",I11*L11,IF(J11="₹/Candy",I11*L11/355.62,IF(J11="₹/Bale",I11*L11/170,I11*L11))) -> 358 | N11: ="₹/kg" -> ₹/kg | O11: ='yarn master raw '!K11 -> Ex-Mill + Freight | P11: ='yarn master raw '!L11 -> No | Q11: ='yarn master raw '!M11 -> Cotton Yarn Price Trend | R11: ='yarn master raw '!N11 -> Historical Price | S11: =IFERROR(IF(ISNUMBER(A11),YEAR(A11),IF(ISNUMBER(SEARCH("'",A11)),VALUE("20"&MID(A11,SEARCH("'",A11)+1,2)),IF(ISNUMBER(SEARCH("2023",A11)),2023,IF(ISNUMBER(SEARCH("2024",A11)),2024,IF(ISNUMBER(SEARCH("2025",A11)),2025,IF(ISNUMBER(SEARCH("2026",A11)),2026,2022)))))),"") -> 2022 | T11: =IFERROR(IF(ISNUMBER(A11),TEXT(A11,"mmmm"),IF(ISNUMBER(SEARCH("Jan",A11)),"January",IF(ISNUMBER(SEARCH("Feb",A11)),"February",IF(ISNUMBER(SEARCH("March",A11)),"March",IF(ISNUMBER(SEARCH("April",A11)),"April",IF(ISNUMBER(SEARCH("May",A11)),"May",IF(ISNUMBER(SEARCH("June",A11)),"June",IF(ISNUMBER(SEARCH("July",A11)),"July",IF(ISNUMBER(SEARCH("Aug",A11)),"August",IF(ISNUMBER(SEARCH("Sep",A11)),"September",IF(ISNUMBER(SEARCH("Oct",A11)),"October",IF(ISNUMBER(SEARCH("Nov",A11)),"November",IF(ISNUMBER(SEARCH("Dec",A11)),"December",""))))))))))))),"") -> August
A12: 44774 | B12: ='yarn master raw '!B12 -> Cotton Yarn | C12: ='yarn master raw '!C12 -> Cotton | D12: =IF('yarn master raw '!J12="INR","India","Imported") -> India | E12: ='yarn master raw '!D12 -> KPR | F12: ='yarn master raw '!E12 -> 34's | G12: ='yarn master raw '!F12 -> Semi-Combed | H12: ='yarn master raw '!G12 -> 100% Cotton | I12: ='yarn master raw '!I12 -> 372 | J12: ='yarn master raw '!H12 -> ₹/kg | K12: ='yarn master raw '!J12 -> INR | L12: =_xlfn.XLOOKUP(K12,'usd inr forecast '!$N$2:$N$6,'usd inr forecast '!$O$2:$O$6,1) -> 1 | M12: =IF(J12="₹/kg",I12*L12,IF(J12="₹/Candy",I12*L12/355.62,IF(J12="₹/Bale",I12*L12/170,I12*L12))) -> 372 | N12: ="₹/kg" -> ₹/kg | O12: ='yarn master raw '!K12 -> Ex-Mill + Freight | P12: ='yarn master raw '!L12 -> No | Q12: ='yarn master raw '!M12 -> Cotton Yarn Price Trend | R12: ='yarn master raw '!N12 -> Historical Price | S12: =IFERROR(IF(ISNUMBER(A12),YEAR(A12),IF(ISNUMBER(SEARCH("'",A12)),VALUE("20"&MID(A12,SEARCH("'",A12)+1,2)),IF(ISNUMBER(SEARCH("2023",A12)),2023,IF(ISNUMBER(SEARCH("2024",A12)),2024,IF(ISNUMBER(SEARCH("2025",A12)),2025,IF(ISNUMBER(SEARCH("2026",A12)),2026,2022)))))),"") -> 2022 | T12: =IFERROR(IF(ISNUMBER(A12),TEXT(A12,"mmmm"),IF(ISNUMBER(SEARCH("Jan",A12)),"January",IF(ISNUMBER(SEARCH("Feb",A12)),"February",IF(ISNUMBER(SEARCH("March",A12)),"March",IF(ISNUMBER(SEARCH("April",A12)),"April",IF(ISNUMBER(SEARCH("May",A12)),"May",IF(ISNUMBER(SEARCH("June",A12)),"June",IF(ISNUMBER(SEARCH("July",A12)),"July",IF(ISNUMBER(SEARCH("Aug",A12)),"August",IF(ISNUMBER(SEARCH("Sep",A12)),"September",IF(ISNUMBER(SEARCH("Oct",A12)),"October",IF(ISNUMBER(SEARCH("Nov",A12)),"November",IF(ISNUMBER(SEARCH("Dec",A12)),"December",""))))))))))))),"") -> August
A13: 44774 | B13: ='yarn master raw '!B13 -> Cotton Yarn | C13: ='yarn master raw '!C13 -> Cotton | D13: =IF('yarn master raw '!J13="INR","India","Imported") -> India | E13: ='yarn master raw '!D13 -> KPR | F13: ='yarn master raw '!E13 -> 40's | G13: ='yarn master raw '!F13 -> Semi-Combed | H13: ='yarn master raw '!G13 -> 100% Cotton | I13: ='yarn master raw '!I13 -> 393 | J13: ='yarn master raw '!H13 -> ₹/kg | K13: ='yarn master raw '!J13 -> INR | L13: =_xlfn.XLOOKUP(K13,'usd inr forecast '!$N$2:$N$6,'usd inr forecast '!$O$2:$O$6,1) -> 1 | M13: =IF(J13="₹/kg",I13*L13,IF(J13="₹/Candy",I13*L13/355.62,IF(J13="₹/Bale",I13*L13/170,I13*L13))) -> 393 | N13: ="₹/kg" -> ₹/kg | O13: ='yarn master raw '!K13 -> Ex-Mill + Freight | P13: ='yarn master raw '!L13 -> No | Q13: ='yarn master raw '!M13 -> Cotton Yarn Price Trend | R13: ='yarn master raw '!N13 -> Historical Price | S13: =IFERROR(IF(ISNUMBER(A13),YEAR(A13),IF(ISNUMBER(SEARCH("'",A13)),VALUE("20"&MID(A13,SEARCH("'",A13)+1,2)),IF(ISNUMBER(SEARCH("2023",A13)),2023,IF(ISNUMBER(SEARCH("2024",A13)),2024,IF(ISNUMBER(SEARCH("2025",A13)),2025,IF(ISNUMBER(SEARCH("2026",A13)),2026,2022)))))),"") -> 2022 | T13: =IFERROR(IF(ISNUMBER(A13),TEXT(A13,"mmmm"),IF(ISNUMBER(SEARCH("Jan",A13)),"January",IF(ISNUMBER(SEARCH("Feb",A13)),"February",IF(ISNUMBER(SEARCH("March",A13)),"March",IF(ISNUMBER(SEARCH("April",A13)),"April",IF(ISNUMBER(SEARCH("May",A13)),"May",IF(ISNUMBER(SEARCH("June",A13)),"June",IF(ISNUMBER(SEARCH("July",A13)),"July",IF(ISNUMBER(SEARCH("Aug",A13)),"August",IF(ISNUMBER(SEARCH("Sep",A13)),"September",IF(ISNUMBER(SEARCH("Oct",A13)),"October",IF(ISNUMBER(SEARCH("Nov",A13)),"November",IF(ISNUMBER(SEARCH("Dec",A13)),"December",""))))))))))))),"") -> August
... A19: 44805 | B19: ='yarn master raw '!B19 -> Cotton Yarn | C19: ='yarn master raw '!C19 -> Cotton | D19: =IF('yarn master raw '!J19="INR","India","Imported") -> India | E19: ='yarn master raw '!D19 -> KPR | F19: ='yarn master raw '!E19 -> 40's | G19: ='yarn master raw '!F19 -> Semi-Combed | H19: ='yarn master raw '!G19 -> 100% Cotton | I19: ='yarn master raw '!I19 -> 393 | J19: ='yarn master raw '!H19 -> ₹/kg | K19: ='yarn master raw '!J19 -> INR | L19: =_xlfn.XLOOKUP(K19,'usd inr forecast '!$N$2:$N$6,'usd inr forecast '!$O$2:$O$6,1) -> 1 | M19: =IF(J19="₹/kg",I19*L19,IF(J19="₹/Candy",I19*L19/355.62,IF(J19="₹/Bale",I19*L19/170,I19*L19))) -> 393 | N19: ="₹/kg" -> ₹/kg | O19: ='yarn master raw '!K19 -> Ex-Mill + Freight | P19: ='yarn master raw '!L19 -> No | Q19: ='yarn master raw '!M19 -> Cotton Yarn Price Trend | R19: ='yarn master raw '!N19 -> Historical Price | S19: =IFERROR(IF(ISNUMBER(A19),YEAR(A19),IF(ISNUMBER(SEARCH("'",A19)),VALUE("20"&MID(A19,SEARCH("'",A19)+1,2)),IF(ISNUMBER(SEARCH("2023",A19)),2023,IF(ISNUMBER(SEARCH("2024",A19)),2024,IF(ISNUMBER(SEARCH("2025",A19)),2025,IF(ISNUMBER(SEARCH("2026",A19)),2026,2022)))))),"") -> 2022 | T19: =IFERROR(IF(ISNUMBER(A19),TEXT(A19,"mmmm"),IF(ISNUMBER(SEARCH("Jan",A19)),"January",IF(ISNUMBER(SEARCH("Feb",A19)),"February",IF(ISNUMBER(SEARCH("March",A19)),"March",IF(ISNUMBER(SEARCH("April",A19)),"April",IF(ISNUMBER(SEARCH("May",A19)),"May",IF(ISNUMBER(SEARCH("June",A19)),"June",IF(ISNUMBER(SEARCH("July",A19)),"July",IF(ISNUMBER(SEARCH("Aug",A19)),"August",IF(ISNUMBER(SEARCH("Sep",A19)),"September",IF(ISNUMBER(SEARCH("Oct",A19)),"October",IF(ISNUMBER(SEARCH("Nov",A19)),"November",IF(ISNUMBER(SEARCH("Dec",A19)),"December",""))))))))))))),"") -> September
A20: ='yarn master raw '!A20 -> 23rd Sept | B20: ='yarn master raw '!B20 -> Cotton Yarn | C20: ='yarn master raw '!C20 -> Cotton | D20: =IF('yarn master raw '!J20="INR","India","Imported") -> India | E20: ='yarn master raw '!D20 -> KPR | F20: ='yarn master raw '!E20 -> 16's | G20: ='yarn master raw '!F20 -> Semi-Combed | H20: ='yarn master raw '!G20 -> 100% Cotton | I20: ='yarn master raw '!I20 -> 334 | J20: ='yarn master raw '!H20 -> ₹/kg | K20: ='yarn master raw '!J20 -> INR | L20: =_xlfn.XLOOKUP(K20,'usd inr forecast '!$N$2:$N$6,'usd inr forecast '!$O$2:$O$6,1) -> 1 | M20: =IF(J20="₹/kg",I20*L20,IF(J20="₹/Candy",I20*L20/355.62,IF(J20="₹/Bale",I20*L20/170,I20*L20))) -> 334 | N20: ="₹/kg" -> ₹/kg | O20: ='yarn master raw '!K20 -> Ex-Mill + Freight | P20: ='yarn master raw '!L20 -> No | Q20: ='yarn master raw '!M20 -> Cotton Yarn Price Trend | R20: ='yarn master raw '!N20 -> Historical Price | S20: =IFERROR(IF(ISNUMBER(A20),YEAR(A20),IF(ISNUMBER(SEARCH("'",A20)),VALUE("20"&MID(A20,SEARCH("'",A20)+1,2)),IF(ISNUMBER(SEARCH("2023",A20)),2023,IF(ISNUMBER(SEARCH("2024",A20)),2024,IF(ISNUMBER(SEARCH("2025",A20)),2025,IF(ISNUMBER(SEARCH("2026",A20)),2026,2022)))))),"") -> 2022 | T20: =IFERROR(IF(ISNUMBER(A20),TEXT(A20,"mmmm"),IF(ISNUMBER(SEARCH("Jan",A20)),"January",IF(ISNUMBER(SEARCH("Feb",A20)),"February",IF(ISNUMBER(SEARCH("March",A20)),"March",IF(ISNUMBER(SEARCH("April",A20)),"April",IF(ISNUMBER(SEARCH("May",A20)),"May",IF(ISNUMBER(SEARCH("June",A20)),"June",IF(ISNUMBER(SEARCH("July",A20)),"July",IF(ISNUMBER(SEARCH("Aug",A20)),"August",IF(ISNUMBER(SEARCH("Sep",A20)),"September",IF(ISNUMBER(SEARCH("Oct",A20)),"October",IF(ISNUMBER(SEARCH("Nov",A20)),"November",IF(ISNUMBER(SEARCH("Dec",A20)),"December",""))))))))))))),"") -> September
A21: ='yarn master raw '!A21 -> 23rd Sept | B21: ='yarn master raw '!B21 -> Cotton Yarn | C21: ='yarn master raw '!C21 -> Cotton | D21: =IF('yarn master raw '!J21="INR","India","Imported") -> India | E21: ='yarn master raw '!D21 -> KPR | F21: ='yarn master raw '!E21 -> 20's | G21: ='yarn master raw '!F21 -> Semi-Combed | H21: ='yarn master raw '!G21 -> 100% Cotton | I21: ='yarn master raw '!I21 -> 337 | J21: ='yarn master raw '!H21 -> ₹/kg | K21: ='yarn master raw '!J21 -> INR | L21: =_xlfn.XLOOKUP(K21,'usd inr forecast '!$N$2:$N$6,'usd inr forecast '!$O$2:$O$6,1) -> 1 | M21: =IF(J21="₹/kg",I21*L21,IF(J21="₹/Candy",I21*L21/355.62,IF(J21="₹/Bale",I21*L21/170,I21*L21))) -> 337 | N21: ="₹/kg" -> ₹/kg | O21: ='yarn master raw '!K21 -> Ex-Mill + Freight | P21: ='yarn master raw '!L21 -> No | Q21: ='yarn master raw '!M21 -> Cotton Yarn Price Trend | R21: ='yarn master raw '!N21 -> Historical Price | S21: =IFERROR(IF(ISNUMBER(A21),YEAR(A21),IF(ISNUMBER(SEARCH("'",A21)),VALUE("20"&MID(A21,SEARCH("'",A21)+1,2)),IF(ISNUMBER(SEARCH("2023",A21)),2023,IF(ISNUMBER(SEARCH("2024",A21)),2024,IF(ISNUMBER(SEARCH("2025",A21)),2025,IF(ISNUMBER(SEARCH("2026",A21)),2026,2022)))))),"") -> 2022 | T21: =IFERROR(IF(ISNUMBER(A21),TEXT(A21,"mmmm"),IF(ISNUMBER(SEARCH("Jan",A21)),"January",IF(ISNUMBER(SEARCH("Feb",A21)),"February",IF(ISNUMBER(SEARCH("March",A21)),"March",IF(ISNUMBER(SEARCH("April",A21)),"April",IF(ISNUMBER(SEARCH("May",A21)),"May",IF(ISNUMBER(SEARCH("June",A21)),"June",IF(ISNUMBER(SEARCH("July",A21)),"July",IF(ISNUMBER(SEARCH("Aug",A21)),"August",IF(ISNUMBER(SEARCH("Sep",A21)),"September",IF(ISNUMBER(SEARCH("Oct",A21)),"October",IF(ISNUMBER(SEARCH("Nov",A21)),"November",IF(ISNUMBER(SEARCH("Dec",A21)),"December",""))))))))))))),"") -> September
A22: ='yarn master raw '!A22 -> 23rd Sept | B22: ='yarn master raw '!B22 -> Cotton Yarn | C22: ='yarn master raw '!C22 -> Cotton | D22: =IF('yarn master raw '!J22="INR","India","Imported") -> India | E22: ='yarn master raw '!D22 -> KPR | F22: ='yarn master raw '!E22 -> 24's | G22: ='yarn master raw '!F22 -> Semi-Combed | H22: ='yarn master raw '!G22 -> 100% Cotton | I22: ='yarn master raw '!I22 -> 346 | J22: ='yarn master raw '!H22 -> ₹/kg | K22: ='yarn master raw '!J22 -> INR | L22: =_xlfn.XLOOKUP(K22,'usd inr forecast '!$N$2:$N$6,'usd inr forecast '!$O$2:$O$6,1) -> 1 | M22: =IF(J22="₹/kg",I22*L22,IF(J22="₹/Candy",I22*L22/355.62,IF(J22="₹/Bale",I22*L22/170,I22*L22))) -> 346 | N22: ="₹/kg" -> ₹/kg | O22: ='yarn master raw '!K22 -> Ex-Mill + Freight | P22: ='yarn master raw '!L22 -> No | Q22: ='yarn master raw '!M22 -> Cotton Yarn Price Trend | R22: ='yarn master raw '!N22 -> Historical Price | S22: =IFERROR(IF(ISNUMBER(A22),YEAR(A22),IF(ISNUMBER(SEARCH("'",A22)),VALUE("20"&MID(A22,SEARCH("'",A22)+1,2)),IF(ISNUMBER(SEARCH("2023",A22)),2023,IF(ISNUMBER(SEARCH("2024",A22)),2024,IF(ISNUMBER(SEARCH("2025",A22)),2025,IF(ISNUMBER(SEARCH("2026",A22)),2026,2022)))))),"") -> 2022 | T22: =IFERROR(IF(ISNUMBER(A22),TEXT(A22,"mmmm"),IF(ISNUMBER(SEARCH("Jan",A22)),"January",IF(ISNUMBER(SEARCH("Feb",A22)),"February",IF(ISNUMBER(SEARCH("March",A22)),"March",IF(ISNUMBER(SEARCH("April",A22)),"April",IF(ISNUMBER(SEARCH("May",A22)),"May",IF(ISNUMBER(SEARCH("June",A22)),"June",IF(ISNUMBER(SEARCH("July",A22)),"July",IF(ISNUMBER(SEARCH("Aug",A22)),"August",IF(ISNUMBER(SEARCH("Sep",A22)),"September",IF(ISNUMBER(SEARCH("Oct",A22)),"October",IF(ISNUMBER(SEARCH("Nov",A22)),"November",IF(ISNUMBER(SEARCH("Dec",A22)),"December",""))))))))))))),"") -> September
A23: ='yarn master raw '!A23 -> 23rd Sept | B23: ='yarn master raw '!B23 -> Cotton Yarn | C23: ='yarn master raw '!C23 -> Cotton | D23: =IF('yarn master raw '!J23="INR","India","Imported") -> India | E23: ='yarn master raw '!D23 -> KPR | F23: ='yarn master raw '!E23 -> 30's | G23: ='yarn master raw '!F23 -> Semi-Combed | H23: ='yarn master raw '!G23 -> 100% Cotton | I23: ='yarn master raw '!I23 -> 358 | J23: ='yarn master raw '!H23 -> ₹/kg | K23: ='yarn master raw '!J23 -> INR | L23: =_xlfn.XLOOKUP(K23,'usd inr forecast '!$N$2:$N$6,'usd inr forecast '!$O$2:$O$6,1) -> 1 | M23: =IF(J23="₹/kg",I23*L23,IF(J23="₹/Candy",I23*L23/355.62,IF(J23="₹/Bale",I23*L23/170,I23*L23))) -> 358 | N23: ="₹/kg" -> ₹/kg | O23: ='yarn master raw '!K23 -> Ex-Mill + Freight | P23: ='yarn master raw '!L23 -> No | Q23: ='yarn master raw '!M23 -> Cotton Yarn Price Trend | R23: ='yarn master raw '!N23 -> Historical Price | S23: =IFERROR(IF(ISNUMBER(A23),YEAR(A23),IF(ISNUMBER(SEARCH("'",A23)),VALUE("20"&MID(A23,SEARCH("'",A23)+1,2)),IF(ISNUMBER(SEARCH("2023",A23)),2023,IF(ISNUMBER(SEARCH("2024",A23)),2024,IF(ISNUMBER(SEARCH("2025",A23)),2025,IF(ISNUMBER(SEARCH("2026",A23)),2026,2022)))))),"") -> 2022 | T23: =IFERROR(IF(ISNUMBER(A23),TEXT(A23,"mmmm"),IF(ISNUMBER(SEARCH("Jan",A23)),"January",IF(ISNUMBER(SEARCH("Feb",A23)),"February",IF(ISNUMBER(SEARCH("March",A23)),"March",IF(ISNUMBER(SEARCH("April",A23)),"April",IF(ISNUMBER(SEARCH("May",A23)),"May",IF(ISNUMBER(SEARCH("June",A23)),"June",IF(ISNUMBER(SEARCH("July",A23)),"July",IF(ISNUMBER(SEARCH("Aug",A23)),"August",IF(ISNUMBER(SEARCH("Sep",A23)),"September",IF(ISNUMBER(SEARCH("Oct",A23)),"October",IF(ISNUMBER(SEARCH("Nov",A23)),"November",IF(ISNUMBER(SEARCH("Dec",A23)),"December",""))))))))))))),"") -> September
A24: ='yarn master raw '!A24 -> 23rd Sept | B24: ='yarn master raw '!B24 -> Cotton Yarn | C24: ='yarn master raw '!C24 -> Cotton | D24: =IF('yarn master raw '!J24="INR","India","Imported") -> India | E24: ='yarn master raw '!D24 -> KPR | F24: ='yarn master raw '!E24 -> 34's | G24: ='yarn master raw '!F24 -> Semi-Combed | H24: ='yarn master raw '!G24 -> 100% Cotton | I24: ='yarn master raw '!I24 -> 372 | J24: ='yarn master raw '!H24 -> ₹/kg | K24: ='yarn master raw '!J24 -> INR | L24: =_xlfn.XLOOKUP(K24,'usd inr forecast '!$N$2:$N$6,'usd inr forecast '!$O$2:$O$6,1) -> 1 | M24: =IF(J24="₹/kg",I24*L24,IF(J24="₹/Candy",I24*L24/355.62,IF(J24="₹/Bale",I24*L24/170,I24*L24))) -> 372 | N24: ="₹/kg" -> ₹/kg | O24: ='yarn master raw '!K24 -> Ex-Mill + Freight | P24: ='yarn master raw '!L24 -> No | Q24: ='yarn master raw '!M24 -> Cotton Yarn Price Trend | R24: ='yarn master raw '!N24 -> Historical Price | S24: =IFERROR(IF(ISNUMBER(A24),YEAR(A24),IF(ISNUMBER(SEARCH("'",A24)),VALUE("20"&MID(A24,SEARCH("'",A24)+1,2)),IF(ISNUMBER(SEARCH("2023",A24)),2023,IF(ISNUMBER(SEARCH("2024",A24)),2024,IF(ISNUMBER(SEARCH("2025",A24)),2025,IF(ISNUMBER(SEARCH("2026",A24)),2026,2022)))))),"") -> 2022 | T24: =IFERROR(IF(ISNUMBER(A24),TEXT(A24,"mmmm"),IF(ISNUMBER(SEARCH("Jan",A24)),"January",IF(ISNUMBER(SEARCH("Feb",A24)),"February",IF(ISNUMBER(SEARCH("March",A24)),"March",IF(ISNUMBER(SEARCH("April",A24)),"April",IF(ISNUMBER(SEARCH("May",A24)),"May",IF(ISNUMBER(SEARCH("June",A24)),"June",IF(ISNUMBER(SEARCH("July",A24)),"July",IF(ISNUMBER(SEARCH("Aug",A24)),"August",IF(ISNUMBER(SEARCH("Sep",A24)),"September",IF(ISNUMBER(SEARCH("Oct",A24)),"October",IF(ISNUMBER(SEARCH("Nov",A24)),"November",IF(ISNUMBER(SEARCH("Dec",A24)),"December",""))))))))))))),"") -> September
A25: ='yarn master raw '!A25 -> 23rd Sept | B25: ='yarn master raw '!B25 -> Cotton Yarn | C25: ='yarn master raw '!C25 -> Cotton | D25: =IF('yarn master raw '!J25="INR","India","Imported") -> India | E25: ='yarn master raw '!D25 -> KPR | F25: ='yarn master raw '!E25 -> 40's | G25: ='yarn master raw '!F25 -> Semi-Combed | H25: ='yarn master raw '!G25 -> 100% Cotton | I25: ='yarn master raw '!I25 -> 393 | J25: ='yarn master raw '!H25 -> ₹/kg | K25: ='yarn master raw '!J25 -> INR | L25: =_xlfn.XLOOKUP(K25,'usd inr forecast '!$N$2:$N$6,'usd inr forecast '!$O$2:$O$6,1) -> 1 | M25: =IF(J25="₹/kg",I25*L25,IF(J25="₹/Candy",I25*L25/355.62,IF(J25="₹/Bale",I25*L25/170,I25*L25))) -> 393 | N25: ="₹/kg" -> ₹/kg | O25: ='yarn master raw '!K25 -> Ex-Mill + Freight | P25: ='yarn master raw '!L25 -> No | Q25: ='yarn master raw '!M25 -> Cotton Yarn Price Trend | R25: ='yarn master raw '!N25 -> Historical Price | S25: =IFERROR(IF(ISNUMBER(A25),YEAR(A25),IF(ISNUMBER(SEARCH("'",A25)),VALUE("20"&MID(A25,SEARCH("'",A25)+1,2)),IF(ISNUMBER(SEARCH("2023",A25)),2023,IF(ISNUMBER(SEARCH("2024",A25)),2024,IF(ISNUMBER(SEARCH("2025",A25)),2025,IF(ISNUMBER(SEARCH("2026",A25)),2026,2022)))))),"") -> 2022 | T25: =IFERROR(IF(ISNUMBER(A25),TEXT(A25,"mmmm"),IF(ISNUMBER(SEARCH("Jan",A25)),"January",IF(ISNUMBER(SEARCH("Feb",A25)),"February",IF(ISNUMBER(SEARCH("March",A25)),"March",IF(ISNUMBER(SEARCH("April",A25)),"April",IF(ISNUMBER(SEARCH("May",A25)),"May",IF(ISNUMBER(SEARCH("June",A25)),"June",IF(ISNUMBER(SEARCH("July",A25)),"July",IF(ISNUMBER(SEARCH("Aug",A25)),"August",IF(ISNUMBER(SEARCH("Sep",A25)),"September",IF(ISNUMBER(SEARCH("Oct",A25)),"October",IF(ISNUMBER(SEARCH("Nov",A25)),"November",IF(ISNUMBER(SEARCH("Dec",A25)),"December",""))))))))))))),"") -> September
A26: ='yarn master raw '!A26 -> 29th Sept | B26: ='yarn master raw '!B26 -> Cotton Yarn | C26: ='yarn master raw '!C26 -> Cotton | D26: =IF('yarn master raw '!J26="INR","India","Imported") -> India | E26: ='yarn master raw '!D26 -> KPR | F26: ='yarn master raw '!E26 -> 16's | G26: ='yarn master raw '!F26 -> Semi-Combed | H26: ='yarn master raw '!G26 -> 100% Cotton | I26: ='yarn master raw '!I26 -> 334 | J26: ='yarn master raw '!H26 -> ₹/kg | K26: ='yarn master raw '!J26 -> INR | L26: =_xlfn.XLOOKUP(K26,'usd inr forecast '!$N$2:$N$6,'usd inr forecast '!$O$2:$O$6,1) -> 1 | M26: =IF(J26="₹/kg",I26*L26,IF(J26="₹/Candy",I26*L26/355.62,IF(J26="₹/Bale",I26*L26/170,I26*L26))) -> 334 | N26: ="₹/kg" -> ₹/kg | O26: ='yarn master raw '!K26 -> Ex-Mill + Freight | P26: ='yarn master raw '!L26 -> No | Q26: ='yarn master raw '!M26 -> Cotton Yarn Price Trend | R26: ='yarn master raw '!N26 -> Historical Price | S26: =IFERROR(IF(ISNUMBER(A26),YEAR(A26),IF(ISNUMBER(SEARCH("'",A26)),VALUE("20"&MID(A26,SEARCH("'",A26)+1,2)),IF(ISNUMBER(SEARCH("2023",A26)),2023,IF(ISNUMBER(SEARCH("2024",A26)),2024,IF(ISNUMBER(SEARCH("2025",A26)),2025,IF(ISNUMBER(SEARCH("2026",A26)),2026,2022)))))),"") -> 2022 | T26: =IFERROR(IF(ISNUMBER(A26),TEXT(A26,"mmmm"),IF(ISNUMBER(SEARCH("Jan",A26)),"January",IF(ISNUMBER(SEARCH("Feb",A26)),"February",IF(ISNUMBER(SEARCH("March",A26)),"March",IF(ISNUMBER(SEARCH("April",A26)),"April",IF(ISNUMBER(SEARCH("May",A26)),"May",IF(ISNUMBER(SEARCH("June",A26)),"June",IF(ISNUMBER(SEARCH("July",A26)),"July",IF(ISNUMBER(SEARCH("Aug",A26)),"August",IF(ISNUMBER(SEARCH("Sep",A26)),"September",IF(ISNUMBER(SEARCH("Oct",A26)),"October",IF(ISNUMBER(SEARCH("Nov",A26)),"November",IF(ISNUMBER(SEARCH("Dec",A26)),"December",""))))))))))))),"") -> September
A27: ='yarn master raw '!A27 -> 29th Sept | B27: ='yarn master raw '!B27 -> Cotton Yarn | C27: ='yarn master raw '!C27 -> Cotton | D27: =IF('yarn master raw '!J27="INR","India","Imported") -> India | E27: ='yarn master raw '!D27 -> KPR | F27: ='yarn master raw '!E27 -> 20's | G27: ='yarn master raw '!F27 -> Semi-Combed | H27: ='yarn master raw '!G27 -> 100% Cotton | I27: ='yarn master raw '!I27 -> 337 | J27: ='yarn master raw '!H27 -> ₹/kg | K27: ='yarn master raw '!J27 -> INR | L27: =_xlfn.XLOOKUP(K27,'usd inr forecast '!$N$2:$N$6,'usd inr forecast '!$O$2:$O$6,1) -> 1 | M27: =IF(J27="₹/kg",I27*L27,IF(J27="₹/Candy",I27*L27/355.62,IF(J27="₹/Bale",I27*L27/170,I27*L27))) -> 337 | N27: ="₹/kg" -> ₹/kg | O27: ='yarn master raw '!K27 -> Ex-Mill + Freight | P27: ='yarn master raw '!L27 -> No | Q27: ='yarn master raw '!M27 -> Cotton Yarn Price Trend | R27: ='yarn master raw '!N27 -> Historical Price | S27: =IFERROR(IF(ISNUMBER(A27),YEAR(A27),IF(ISNUMBER(SEARCH("'",A27)),VALUE("20"&MID(A27,SEARCH("'",A27)+1,2)),IF(ISNUMBER(SEARCH("2023",A27)),2023,IF(ISNUMBER(SEARCH("2024",A27)),2024,IF(ISNUMBER(SEARCH("2025",A27)),2025,IF(ISNUMBER(SEARCH("2026",A27)),2026,2022)))))),"") -> 2022 | T27: =IFERROR(IF(ISNUMBER(A27),TEXT(A27,"mmmm"),IF(ISNUMBER(SEARCH("Jan",A27)),"January",IF(ISNUMBER(SEARCH("Feb",A27)),"February",IF(ISNUMBER(SEARCH("March",A27)),"March",IF(ISNUMBER(SEARCH("April",A27)),"April",IF(ISNUMBER(SEARCH("May",A27)),"May",IF(ISNUMBER(SEARCH("June",A27)),"June",IF(ISNUMBER(SEARCH("July",A27)),"July",IF(ISNUMBER(SEARCH("Aug",A27)),"August",IF(ISNUMBER(SEARCH("Sep",A27)),"September",IF(ISNUMBER(SEARCH("Oct",A27)),"October",IF(ISNUMBER(SEARCH("Nov",A27)),"November",IF(ISNUMBER(SEARCH("Dec",A27)),"December",""))))))))))))),"") -> September
A28: ='yarn master raw '!A28 -> 29th Sept | B28: ='yarn master raw '!B28 -> Cotton Yarn | C28: ='yarn master raw '!C28 -> Cotton | D28: =IF('yarn master raw '!J28="INR","India","Imported") -> India | E28: ='yarn master raw '!D28 -> KPR | F28: ='yarn master raw '!E28 -> 24's | G28: ='yarn master raw '!F28 -> Semi-Combed | H28: ='yarn master raw '!G28 -> 100% Cotton | I28: ='yarn master raw '!I28 -> 346 | J28: ='yarn master raw '!H28 -> ₹/kg | K28: ='yarn master raw '!J28 -> INR | L28: =_xlfn.XLOOKUP(K28,'usd inr forecast '!$N$2:$N$6,'usd inr forecast '!$O$2:$O$6,1) -> 1 | M28: =IF(J28="₹/kg",I28*L28,IF(J28="₹/Candy",I28*L28/355.62,IF(J28="₹/Bale",I28*L28/170,I28*L28))) -> 346 | N28: ="₹/kg" -> ₹/kg | O28: ='yarn master raw '!K28 -> Ex-Mill + Freight | P28: ='yarn master raw '!L28 -> No | Q28: ='yarn master raw '!M28 -> Cotton Yarn Price Trend | R28: ='yarn master raw '!N28 -> Historical Price | S28: =IFERROR(IF(ISNUMBER(A28),YEAR(A28),IF(ISNUMBER(SEARCH("'",A28)),VALUE("20"&MID(A28,SEARCH("'",A28)+1,2)),IF(ISNUMBER(SEARCH("2023",A28)),2023,IF(ISNUMBER(SEARCH("2024",A28)),2024,IF(ISNUMBER(SEARCH("2025",A28)),2025,IF(ISNUMBER(SEARCH("2026",A28)),2026,2022)))))),"") -> 2022 | T28: =IFERROR(IF(ISNUMBER(A28),TEXT(A28,"mmmm"),IF(ISNUMBER(SEARCH("Jan",A28)),"January",IF(ISNUMBER(SEARCH("Feb",A28)),"February",IF(ISNUMBER(SEARCH("March",A28)),"March",IF(ISNUMBER(SEARCH("April",A28)),"April",IF(ISNUMBER(SEARCH("May",A28)),"May",IF(ISNUMBER(SEARCH("June",A28)),"June",IF(ISNUMBER(SEARCH("July",A28)),"July",IF(ISNUMBER(SEARCH("Aug",A28)),"August",IF(ISNUMBER(SEARCH("Sep",A28)),"September",IF(ISNUMBER(SEARCH("Oct",A28)),"October",IF(ISNUMBER(SEARCH("Nov",A28)),"November",IF(ISNUMBER(SEARCH("Dec",A28)),"December",""))))))))))))),"") -> September
A29: ='yarn master raw '!A29 -> 29th Sept | B29: ='yarn master raw '!B29 -> Cotton Yarn | C29: ='yarn master raw '!C29 -> Cotton | D29: =IF('yarn master raw '!J29="INR","India","Imported") -> India | E29: ='yarn master raw '!D29 -> KPR | F29: ='yarn master raw '!E29 -> 30's | G29: ='yarn master raw '!F29 -> Semi-Combed | H29: ='yarn master raw '!G29 -> 100% Cotton | I29: ='yarn master raw '!I29 -> 358 | J29: ='yarn master raw '!H29 -> ₹/kg | K29: ='yarn master raw '!J29 -> INR | L29: =_xlfn.XLOOKUP(K29,'usd inr forecast '!$N$2:$N$6,'usd inr forecast '!$O$2:$O$6,1) -> 1 | M29: =IF(J29="₹/kg",I29*L29,IF(J29="₹/Candy",I29*L29/355.62,IF(J29="₹/Bale",I29*L29/170,I29*L29))) -> 358 | N29: ="₹/kg" -> ₹/kg | O29: ='yarn master raw '!K29 -> Ex-Mill + Freight | P29: ='yarn master raw '!L29 -> No | Q29: ='yarn master raw '!M29 -> Cotton Yarn Price Trend | R29: ='yarn master raw '!N29 -> Historical Price | S29: =IFERROR(IF(ISNUMBER(A29),YEAR(A29),IF(ISNUMBER(SEARCH("'",A29)),VALUE("20"&MID(A29,SEARCH("'",A29)+1,2)),IF(ISNUMBER(SEARCH("2023",A29)),2023,IF(ISNUMBER(SEARCH("2024",A29)),2024,IF(ISNUMBER(SEARCH("2025",A29)),2025,IF(ISNUMBER(SEARCH("2026",A29)),2026,2022)))))),"") -> 2022 | T29: =IFERROR(IF(ISNUMBER(A29),TEXT(A29,"mmmm"),IF(ISNUMBER(SEARCH("Jan",A29)),"January",IF(ISNUMBER(SEARCH("Feb",A29)),"February",IF(ISNUMBER(SEARCH("March",A29)),"March",IF(ISNUMBER(SEARCH("April",A29)),"April",IF(ISNUMBER(SEARCH("May",A29)),"May",IF(ISNUMBER(SEARCH("June",A29)),"June",IF(ISNUMBER(SEARCH("July",A29)),"July",IF(ISNUMBER(SEARCH("Aug",A29)),"August",IF(ISNUMBER(SEARCH("Sep",A29)),"September",IF(ISNUMBER(SEARCH("Oct",A29)),"October",IF(ISNUMBER(SEARCH("Nov",A29)),"November",IF(ISNUMBER(SEARCH("Dec",A29)),"December",""))))))))))))),"") -> September
A30: ='yarn master raw '!A30 -> 29th Sept | B30: ='yarn master raw '!B30 -> Cotton Yarn | C30: ='yarn master raw '!C30 -> Cotton | D30: =IF('yarn master raw '!J30="INR","India","Imported") -> India | E30: ='yarn master raw '!D30 -> KPR | F30: ='yarn master raw '!E30 -> 34's | G30: ='yarn master raw '!F30 -> Semi-Combed | H30: ='yarn master raw '!G30 -> 100% Cotton | I30: ='yarn master raw '!I30 -> 372 | J30: ='yarn master raw '!H30 -> ₹/kg | K30: ='yarn master raw '!J30 -> INR | L30: =_xlfn.XLOOKUP(K30,'usd inr forecast '!$N$2:$N$6,'usd inr forecast '!$O$2:$O$6,1) -> 1 | M30: =IF(J30="₹/kg",I30*L30,IF(J30="₹/Candy",I30*L30/355.62,IF(J30="₹/Bale",I30*L30/170,I30*L30))) -> 372 | N30: ="₹/kg" -> ₹/kg | O30: ='yarn master raw '!K30 -> Ex-Mill + Freight | P30: ='yarn master raw '!L30 -> No | Q30: ='yarn master raw '!M30 -> Cotton Yarn Price Trend | R30: ='yarn master raw '!N30 -> Historical Price | S30: =IFERROR(IF(ISNUMBER(A30),YEAR(A30),IF(ISNUMBER(SEARCH("'",A30)),VALUE("20"&MID(A30,SEARCH("'",A30)+1,2)),IF(ISNUMBER(SEARCH("2023",A30)),2023,IF(ISNUMBER(SEARCH("2024",A30)),2024,IF(ISNUMBER(SEARCH("2025",A30)),2025,IF(ISNUMBER(SEARCH("2026",A30)),2026,2022)))))),"") -> 2022 | T30: =IFERROR(IF(ISNUMBER(A30),TEXT(A30,"mmmm"),IF(ISNUMBER(SEARCH("Jan",A30)),"January",IF(ISNUMBER(SEARCH("Feb",A30)),"February",IF(ISNUMBER(SEARCH("March",A30)),"March",IF(ISNUMBER(SEARCH("April",A30)),"April",IF(ISNUMBER(SEARCH("May",A30)),"May",IF(ISNUMBER(SEARCH("June",A30)),"June",IF(ISNUMBER(SEARCH("July",A30)),"July",IF(ISNUMBER(SEARCH("Aug",A30)),"August",IF(ISNUMBER(SEARCH("Sep",A30)),"September",IF(ISNUMBER(SEARCH("Oct",A30)),"October",IF(ISNUMBER(SEARCH("Nov",A30)),"November",IF(ISNUMBER(SEARCH("Dec",A30)),"December",""))))))))))))),"") -> September
A31: ='yarn master raw '!A31 -> 29th Sept | B31: ='yarn master raw '!B31 -> Cotton Yarn | C31: ='yarn master raw '!C31 -> Cotton | D31: =IF('yarn master raw '!J31="INR","India","Imported") -> India | E31: ='yarn master raw '!D31 -> KPR | F31: ='yarn master raw '!E31 -> 40's | G31: ='yarn master raw '!F31 -> Semi-Combed | H31: ='yarn master raw '!G31 -> 100% Cotton | I31: ='yarn master raw '!I31 -> 393 | J31: ='yarn master raw '!H31 -> ₹/kg | K31: ='yarn master raw '!J31 -> INR | L31: =_xlfn.XLOOKUP(K31,'usd inr forecast '!$N$2:$N$6,'usd inr forecast '!$O$2:$O$6,1) -> 1 | M31: =IF(J31="₹/kg",I31*L31,IF(J31="₹/Candy",I31*L31/355.62,IF(J31="₹/Bale",I31*L31/170,I31*L31))) -> 393 | N31: ="₹/kg" -> ₹/kg | O31: ='yarn master raw '!K31 -> Ex-Mill + Freight | P31: ='yarn master raw '!L31 -> No | Q31: ='yarn master raw '!M31 -> Cotton Yarn Price Trend | R31: ='yarn master raw '!N31 -> Historical Price | S31: =IFERROR(IF(ISNUMBER(A31),YEAR(A31),IF(ISNUMBER(SEARCH("'",A31)),VALUE("20"&MID(A31,SEARCH("'",A31)+1,2)),IF(ISNUMBER(SEARCH("2023",A31)),2023,IF(ISNUMBER(SEARCH("2024",A31)),2024,IF(ISNUMBER(SEARCH("2025",A31)),2025,IF(ISNUMBER(SEARCH("2026",A31)),2026,2022)))))),"") -> 2022 | T31: =IFERROR(IF(ISNUMBER(A31),TEXT(A31,"mmmm"),IF(ISNUMBER(SEARCH("Jan",A31)),"January",IF(ISNUMBER(SEARCH("Feb",A31)),"February",IF(ISNUMBER(SEARCH("March",A31)),"March",IF(ISNUMBER(SEARCH("April",A31)),"April",IF(ISNUMBER(SEARCH("May",A31)),"May",IF(ISNUMBER(SEARCH("June",A31)),"June",IF(ISNUMBER(SEARCH("July",A31)),"July",IF(ISNUMBER(SEARCH("Aug",A31)),"August",IF(ISNUMBER(SEARCH("Sep",A31)),"September",IF(ISNUMBER(SEARCH("Oct",A31)),"October",IF(ISNUMBER(SEARCH("Nov",A31)),"November",IF(ISNUMBER(SEARCH("Dec",A31)),"December",""))))))))))))),"") -> September
... A289: ='yarn master raw '!A289 -> 04th Feb 2026 | B289: ='yarn master raw '!B289 -> Cotton Yarn | C289: ='yarn master raw '!C289 -> Cotton | D289: =IF('yarn master raw '!J289="INR","India","Imported") -> India | E289: ='yarn master raw '!D289 -> KPR | F289: ='yarn master raw '!E289 -> 40's | G289: ='yarn master raw '!F289 -> Semi-Combed | H289: ='yarn master raw '!G289 -> 100% Cotton | I289: ='yarn master raw '!I289 -> 313 | J289: ='yarn master raw '!H289 -> ₹/kg | K289: ='yarn master raw '!J289 -> INR | L289: =_xlfn.XLOOKUP(K289,'usd inr forecast '!$N$2:$N$6,'usd inr forecast '!$O$2:$O$6,1) -> 1 | M289: =IF(J289="₹/kg",I289*L289,IF(J289="₹/Candy",I289*L289/355.62,IF(J289="₹/Bale",I289*L289/170,I289*L289))) -> 313 | N289: ="₹/kg" -> ₹/kg | O289: ='yarn master raw '!K289 -> Ex-Mill + Freight | P289: ='yarn master raw '!L289 -> Yes | Q289: ='yarn master raw '!M289 -> Cotton Yarn Price Trend | R289: ='yarn master raw '!N289 -> Historical Price | S289: =IFERROR(IF(ISNUMBER(A289),YEAR(A289),IF(ISNUMBER(SEARCH("'",A289)),VALUE("20"&MID(A289,SEARCH("'",A289)+1,2)),IF(ISNUMBER(SEARCH("2023",A289)),2023,IF(ISNUMBER(SEARCH("2024",A289)),2024,IF(ISNUMBER(SEARCH("2025",A289)),2025,IF(ISNUMBER(SEARCH("2026",A289)),2026,2022)))))),"") -> 2026 | T289: =IFERROR(IF(ISNUMBER(A289),TEXT(A289,"mmmm"),IF(ISNUMBER(SEARCH("Jan",A289)),"January",IF(ISNUMBER(SEARCH("Feb",A289)),"February",IF(ISNUMBER(SEARCH("March",A289)),"March",IF(ISNUMBER(SEARCH("April",A289)),"April",IF(ISNUMBER(SEARCH("May",A289)),"May",IF(ISNUMBER(SEARCH("June",A289)),"June",IF(ISNUMBER(SEARCH("July",A289)),"July",IF(ISNUMBER(SEARCH("Aug",A289)),"August",IF(ISNUMBER(SEARCH("Sep",A289)),"September",IF(ISNUMBER(SEARCH("Oct",A289)),"October",IF(ISNUMBER(SEARCH("Nov",A289)),"November",IF(ISNUMBER(SEARCH("Dec",A289)),"December",""))))))))))))),"") -> February
A290: ='yarn master raw '!A290 -> 07th Mar 2026 | B290: ='yarn master raw '!B290 -> Cotton Yarn | C290: ='yarn master raw '!C290 -> Cotton | D290: =IF('yarn master raw '!J290="INR","India","Imported") -> India | E290: ='yarn master raw '!D290 -> KPR | F290: ='yarn master raw '!E290 -> 16's | G290: ='yarn master raw '!F290 -> Semi-Combed | H290: ='yarn master raw '!G290 -> 100% Cotton | I290: ='yarn master raw '!I290 -> 264 | J290: ='yarn master raw '!H290 -> ₹/kg | K290: ='yarn master raw '!J290 -> INR | L290: =_xlfn.XLOOKUP(K290,'usd inr forecast '!$N$2:$N$6,'usd inr forecast '!$O$2:$O$6,1) -> 1 | M290: =IF(J290="₹/kg",I290*L290,IF(J290="₹/Candy",I290*L290/355.62,IF(J290="₹/Bale",I290*L290/170,I290*L290))) -> 264 | N290: ="₹/kg" -> ₹/kg | O290: ='yarn master raw '!K290 -> Ex-Mill + Freight | P290: ='yarn master raw '!L290 -> Yes | Q290: ='yarn master raw '!M290 -> Cotton Yarn Price Trend | R290: ='yarn master raw '!N290 -> Historical Price | S290: =IFERROR(IF(ISNUMBER(A290),YEAR(A290),IF(ISNUMBER(SEARCH("'",A290)),VALUE("20"&MID(A290,SEARCH("'",A290)+1,2)),IF(ISNUMBER(SEARCH("2023",A290)),2023,IF(ISNUMBER(SEARCH("2024",A290)),2024,IF(ISNUMBER(SEARCH("2025",A290)),2025,IF(ISNUMBER(SEARCH("2026",A290)),2026,2022)))))),"") -> 2026 | T290: March
A291: ='yarn master raw '!A291 -> 07th Mar 2026 | B291: ='yarn master raw '!B291 -> Cotton Yarn | C291: ='yarn master raw '!C291 -> Cotton | D291: =IF('yarn master raw '!J291="INR","India","Imported") -> India | E291: ='yarn master raw '!D291 -> KPR | F291: ='yarn master raw '!E291 -> 20's | G291: ='yarn master raw '!F291 -> Semi-Combed | H291: ='yarn master raw '!G291 -> 100% Cotton | I291: ='yarn master raw '!I291 -> 264 | J291: ='yarn master raw '!H291 -> ₹/kg | K291: ='yarn master raw '!J291 -> INR | L291: =_xlfn.XLOOKUP(K291,'usd inr forecast '!$N$2:$N$6,'usd inr forecast '!$O$2:$O$6,1) -> 1 | M291: =IF(J291="₹/kg",I291*L291,IF(J291="₹/Candy",I291*L291/355.62,IF(J291="₹/Bale",I291*L291/170,I291*L291))) -> 264 | N291: ="₹/kg" -> ₹/kg | O291: ='yarn master raw '!K291 -> Ex-Mill + Freight | P291: ='yarn master raw '!L291 -> Yes | Q291: ='yarn master raw '!M291 -> Cotton Yarn Price Trend | R291: ='yarn master raw '!N291 -> Historical Price | S291: =IFERROR(IF(ISNUMBER(A291),YEAR(A291),IF(ISNUMBER(SEARCH("'",A291)),VALUE("20"&MID(A291,SEARCH("'",A291)+1,2)),IF(ISNUMBER(SEARCH("2023",A291)),2023,IF(ISNUMBER(SEARCH("2024",A291)),2024,IF(ISNUMBER(SEARCH("2025",A291)),2025,IF(ISNUMBER(SEARCH("2026",A291)),2026,2022)))))),"") -> 2026 | T291: March
A292: ='yarn master raw '!A292 -> 07th Mar 2026 | B292: ='yarn master raw '!B292 -> Cotton Yarn | C292: ='yarn master raw '!C292 -> Cotton | D292: =IF('yarn master raw '!J292="INR","India","Imported") -> India | E292: ='yarn master raw '!D292 -> KPR | F292: ='yarn master raw '!E292 -> 24's | G292: ='yarn master raw '!F292 -> Semi-Combed | H292: ='yarn master raw '!G292 -> 100% Cotton | I292: ='yarn master raw '!I292 -> 273 | J292: ='yarn master raw '!H292 -> ₹/kg | K292: ='yarn master raw '!J292 -> INR | L292: =_xlfn.XLOOKUP(K292,'usd inr forecast '!$N$2:$N$6,'usd inr forecast '!$O$2:$O$6,1) -> 1 | M292: =IF(J292="₹/kg",I292*L292,IF(J292="₹/Candy",I292*L292/355.62,IF(J292="₹/Bale",I292*L292/170,I292*L292))) -> 273 | N292: ="₹/kg" -> ₹/kg | O292: ='yarn master raw '!K292 -> Ex-Mill + Freight | P292: ='yarn master raw '!L292 -> Yes | Q292: ='yarn master raw '!M292 -> Cotton Yarn Price Trend | R292: ='yarn master raw '!N292 -> Historical Price | S292: =IFERROR(IF(ISNUMBER(A292),YEAR(A292),IF(ISNUMBER(SEARCH("'",A292)),VALUE("20"&MID(A292,SEARCH("'",A292)+1,2)),IF(ISNUMBER(SEARCH("2023",A292)),2023,IF(ISNUMBER(SEARCH("2024",A292)),2024,IF(ISNUMBER(SEARCH("2025",A292)),2025,IF(ISNUMBER(SEARCH("2026",A292)),2026,2022)))))),"") -> 2026 | T292: March
A293: ='yarn master raw '!A293 -> 07th Mar 2026 | B293: ='yarn master raw '!B293 -> Cotton Yarn | C293: ='yarn master raw '!C293 -> Cotton | D293: =IF('yarn master raw '!J293="INR","India","Imported") -> India | E293: ='yarn master raw '!D293 -> KPR | F293: ='yarn master raw '!E293 -> 30's | G293: ='yarn master raw '!F293 -> Semi-Combed | H293: ='yarn master raw '!G293 -> 100% Cotton | I293: ='yarn master raw '!I293 -> 285 | J293: ='yarn master raw '!H293 -> ₹/kg | K293: ='yarn master raw '!J293 -> INR | L293: =_xlfn.XLOOKUP(K293,'usd inr forecast '!$N$2:$N$6,'usd inr forecast '!$O$2:$O$6,1) -> 1 | M293: =IF(J293="₹/kg",I293*L293,IF(J293="₹/Candy",I293*L293/355.62,IF(J293="₹/Bale",I293*L293/170,I293*L293))) -> 285 | N293: ="₹/kg" -> ₹/kg | O293: ='yarn master raw '!K293 -> Ex-Mill + Freight | P293: ='yarn master raw '!L293 -> Yes | Q293: ='yarn master raw '!M293 -> Cotton Yarn Price Trend | R293: ='yarn master raw '!N293 -> Historical Price | S293: =IFERROR(IF(ISNUMBER(A293),YEAR(A293),IF(ISNUMBER(SEARCH("'",A293)),VALUE("20"&MID(A293,SEARCH("'",A293)+1,2)),IF(ISNUMBER(SEARCH("2023",A293)),2023,IF(ISNUMBER(SEARCH("2024",A293)),2024,IF(ISNUMBER(SEARCH("2025",A293)),2025,IF(ISNUMBER(SEARCH("2026",A293)),2026,2022)))))),"") -> 2026 | T293: March
A294: ='yarn master raw '!A294 -> 07th Mar 2026 | B294: ='yarn master raw '!B294 -> Cotton Yarn | C294: ='yarn master raw '!C294 -> Cotton | D294: =IF('yarn master raw '!J294="INR","India","Imported") -> India | E294: ='yarn master raw '!D294 -> KPR | F294: ='yarn master raw '!E294 -> 34's | G294: ='yarn master raw '!F294 -> Semi-Combed | H294: ='yarn master raw '!G294 -> 100% Cotton | I294: ='yarn master raw '!I294 -> 292 | J294: ='yarn master raw '!H294 -> ₹/kg | K294: ='yarn master raw '!J294 -> INR | L294: =_xlfn.XLOOKUP(K294,'usd inr forecast '!$N$2:$N$6,'usd inr forecast '!$O$2:$O$6,1) -> 1 | M294: =IF(J294="₹/kg",I294*L294,IF(J294="₹/Candy",I294*L294/355.62,IF(J294="₹/Bale",I294*L294/170,I294*L294))) -> 292 | N294: ="₹/kg" -> ₹/kg | O294: ='yarn master raw '!K294 -> Ex-Mill + Freight | P294: ='yarn master raw '!L294 -> Yes | Q294: ='yarn master raw '!M294 -> Cotton Yarn Price Trend | R294: ='yarn master raw '!N294 -> Historical Price | S294: =IFERROR(IF(ISNUMBER(A294),YEAR(A294),IF(ISNUMBER(SEARCH("'",A294)),VALUE("20"&MID(A294,SEARCH("'",A294)+1,2)),IF(ISNUMBER(SEARCH("2023",A294)),2023,IF(ISNUMBER(SEARCH("2024",A294)),2024,IF(ISNUMBER(SEARCH("2025",A294)),2025,IF(ISNUMBER(SEARCH("2026",A294)),2026,2022)))))),"") -> 2026 | T294: March
A295: ='yarn master raw '!A295 -> 07th Mar 2026 | B295: ='yarn master raw '!B295 -> Cotton Yarn | C295: ='yarn master raw '!C295 -> Cotton | D295: =IF('yarn master raw '!J295="INR","India","Imported") -> India | E295: ='yarn master raw '!D295 -> KPR | F295: ='yarn master raw '!E295 -> 40's | G295: ='yarn master raw '!F295 -> Semi-Combed | H295: ='yarn master raw '!G295 -> 100% Cotton | I295: ='yarn master raw '!I295 -> 313 | J295: ='yarn master raw '!H295 -> ₹/kg | K295: ='yarn master raw '!J295 -> INR | L295: =_xlfn.XLOOKUP(K295,'usd inr forecast '!$N$2:$N$6,'usd inr forecast '!$O$2:$O$6,1) -> 1 | M295: =IF(J295="₹/kg",I295*L295,IF(J295="₹/Candy",I295*L295/355.62,IF(J295="₹/Bale",I295*L295/170,I295*L295))) -> 313 | N295: ="₹/kg" -> ₹/kg | O295: ='yarn master raw '!K295 -> Ex-Mill + Freight | P295: ='yarn master raw '!L295 -> Yes | Q295: ='yarn master raw '!M295 -> Cotton Yarn Price Trend | R295: ='yarn master raw '!N295 -> Historical Price | S295: =IFERROR(IF(ISNUMBER(A295),YEAR(A295),IF(ISNUMBER(SEARCH("'",A295)),VALUE("20"&MID(A295,SEARCH("'",A295)+1,2)),IF(ISNUMBER(SEARCH("2023",A295)),2023,IF(ISNUMBER(SEARCH("2024",A295)),2024,IF(ISNUMBER(SEARCH("2025",A295)),2025,IF(ISNUMBER(SEARCH("2026",A295)),2026,2022)))))),"") -> 2026 | T295: March
A296: ='yarn master raw '!A296 -> 20th Mar 2026 | B296: ='yarn master raw '!B296 -> Cotton Yarn | C296: ='yarn master raw '!C296 -> Cotton | D296: =IF('yarn master raw '!J296="INR","India","Imported") -> India | E296: ='yarn master raw '!D296 -> KPR | F296: ='yarn master raw '!E296 -> 16's | G296: ='yarn master raw '!F296 -> Semi-Combed | H296: ='yarn master raw '!G296 -> 100% Cotton | I296: ='yarn master raw '!I296 -> 264 | J296: ='yarn master raw '!H296 -> ₹/kg | K296: ='yarn master raw '!J296 -> INR | L296: =_xlfn.XLOOKUP(K296,'usd inr forecast '!$N$2:$N$6,'usd inr forecast '!$O$2:$O$6,1) -> 1 | M296: =IF(J296="₹/kg",I296*L296,IF(J296="₹/Candy",I296*L296/355.62,IF(J296="₹/Bale",I296*L296/170,I296*L296))) -> 264 | N296: ="₹/kg" -> ₹/kg | O296: ='yarn master raw '!K296 -> Ex-Mill + Freight | P296: ='yarn master raw '!L296 -> Yes | Q296: ='yarn master raw '!M296 -> Cotton Yarn Price Trend | R296: ='yarn master raw '!N296 -> Historical Price | S296: =IFERROR(IF(ISNUMBER(A296),YEAR(A296),IF(ISNUMBER(SEARCH("'",A296)),VALUE("20"&MID(A296,SEARCH("'",A296)+1,2)),IF(ISNUMBER(SEARCH("2023",A296)),2023,IF(ISNUMBER(SEARCH("2024",A296)),2024,IF(ISNUMBER(SEARCH("2025",A296)),2025,IF(ISNUMBER(SEARCH("2026",A296)),2026,2022)))))),"") -> 2026 | T296: March
A297: ='yarn master raw '!A297 -> 20th Mar 2026 | B297: ='yarn master raw '!B297 -> Cotton Yarn | C297: ='yarn master raw '!C297 -> Cotton | D297: =IF('yarn master raw '!J297="INR","India","Imported") -> India | E297: ='yarn master raw '!D297 -> KPR | F297: ='yarn master raw '!E297 -> 20's | G297: ='yarn master raw '!F297 -> Semi-Combed | H297: ='yarn master raw '!G297 -> 100% Cotton | I297: ='yarn master raw '!I297 -> 264 | J297: ='yarn master raw '!H297 -> ₹/kg | K297: ='yarn master raw '!J297 -> INR | L297: =_xlfn.XLOOKUP(K297,'usd inr forecast '!$N$2:$N$6,'usd inr forecast '!$O$2:$O$6,1) -> 1 | M297: =IF(J297="₹/kg",I297*L297,IF(J297="₹/Candy",I297*L297/355.62,IF(J297="₹/Bale",I297*L297/170,I297*L297))) -> 264 | N297: ="₹/kg" -> ₹/kg | O297: ='yarn master raw '!K297 -> Ex-Mill + Freight | P297: ='yarn master raw '!L297 -> Yes | Q297: ='yarn master raw '!M297 -> Cotton Yarn Price Trend | R297: ='yarn master raw '!N297 -> Historical Price | S297: =IFERROR(IF(ISNUMBER(A297),YEAR(A297),IF(ISNUMBER(SEARCH("'",A297)),VALUE("20"&MID(A297,SEARCH("'",A297)+1,2)),IF(ISNUMBER(SEARCH("2023",A297)),2023,IF(ISNUMBER(SEARCH("2024",A297)),2024,IF(ISNUMBER(SEARCH("2025",A297)),2025,IF(ISNUMBER(SEARCH("2026",A297)),2026,2022)))))),"") -> 2026 | T297: March
A298: ='yarn master raw '!A298 -> 20th Mar 2026 | B298: ='yarn master raw '!B298 -> Cotton Yarn | C298: ='yarn master raw '!C298 -> Cotton | D298: =IF('yarn master raw '!J298="INR","India","Imported") -> India | E298: ='yarn master raw '!D298 -> KPR | F298: ='yarn master raw '!E298 -> 24's | G298: ='yarn master raw '!F298 -> Semi-Combed | H298: ='yarn master raw '!G298 -> 100% Cotton | I298: ='yarn master raw '!I298 -> 273 | J298: ='yarn master raw '!H298 -> ₹/kg | K298: ='yarn master raw '!J298 -> INR | L298: =_xlfn.XLOOKUP(K298,'usd inr forecast '!$N$2:$N$6,'usd inr forecast '!$O$2:$O$6,1) -> 1 | M298: =IF(J298="₹/kg",I298*L298,IF(J298="₹/Candy",I298*L298/355.62,IF(J298="₹/Bale",I298*L298/170,I298*L298))) -> 273 | N298: ="₹/kg" -> ₹/kg | O298: ='yarn master raw '!K298 -> Ex-Mill + Freight | P298: ='yarn master raw '!L298 -> Yes | Q298: ='yarn master raw '!M298 -> Cotton Yarn Price Trend | R298: ='yarn master raw '!N298 -> Historical Price | S298: =IFERROR(IF(ISNUMBER(A298),YEAR(A298),IF(ISNUMBER(SEARCH("'",A298)),VALUE("20"&MID(A298,SEARCH("'",A298)+1,2)),IF(ISNUMBER(SEARCH("2023",A298)),2023,IF(ISNUMBER(SEARCH("2024",A298)),2024,IF(ISNUMBER(SEARCH("2025",A298)),2025,IF(ISNUMBER(SEARCH("2026",A298)),2026,2022)))))),"") -> 2026 | T298: March
A299: ='yarn master raw '!A299 -> 20th Mar 2026 | B299: ='yarn master raw '!B299 -> Cotton Yarn | C299: ='yarn master raw '!C299 -> Cotton | D299: =IF('yarn master raw '!J299="INR","India","Imported") -> India | E299: ='yarn master raw '!D299 -> KPR | F299: ='yarn master raw '!E299 -> 30's | G299: ='yarn master raw '!F299 -> Semi-Combed | H299: ='yarn master raw '!G299 -> 100% Cotton | I299: ='yarn master raw '!I299 -> 285 | J299: ='yarn master raw '!H299 -> ₹/kg | K299: ='yarn master raw '!J299 -> INR | L299: =_xlfn.XLOOKUP(K299,'usd inr forecast '!$N$2:$N$6,'usd inr forecast '!$O$2:$O$6,1) -> 1 | M299: =IF(J299="₹/kg",I299*L299,IF(J299="₹/Candy",I299*L299/355.62,IF(J299="₹/Bale",I299*L299/170,I299*L299))) -> 285 | N299: ="₹/kg" -> ₹/kg | O299: ='yarn master raw '!K299 -> Ex-Mill + Freight | P299: ='yarn master raw '!L299 -> Yes | Q299: ='yarn master raw '!M299 -> Cotton Yarn Price Trend | R299: ='yarn master raw '!N299 -> Historical Price | S299: =IFERROR(IF(ISNUMBER(A299),YEAR(A299),IF(ISNUMBER(SEARCH("'",A299)),VALUE("20"&MID(A299,SEARCH("'",A299)+1,2)),IF(ISNUMBER(SEARCH("2023",A299)),2023,IF(ISNUMBER(SEARCH("2024",A299)),2024,IF(ISNUMBER(SEARCH("2025",A299)),2025,IF(ISNUMBER(SEARCH("2026",A299)),2026,2022)))))),"") -> 2026 | T299: March
A300: ='yarn master raw '!A300 -> 20th Mar 2026 | B300: ='yarn master raw '!B300 -> Cotton Yarn | C300: ='yarn master raw '!C300 -> Cotton | D300: =IF('yarn master raw '!J300="INR","India","Imported") -> India | E300: ='yarn master raw '!D300 -> KPR | F300: ='yarn master raw '!E300 -> 34's | G300: ='yarn master raw '!F300 -> Semi-Combed | H300: ='yarn master raw '!G300 -> 100% Cotton | I300: ='yarn master raw '!I300 -> 292 | J300: ='yarn master raw '!H300 -> ₹/kg | K300: ='yarn master raw '!J300 -> INR | L300: =_xlfn.XLOOKUP(K300,'usd inr forecast '!$N$2:$N$6,'usd inr forecast '!$O$2:$O$6,1) -> 1 | M300: =IF(J300="₹/kg",I300*L300,IF(J300="₹/Candy",I300*L300/355.62,IF(J300="₹/Bale",I300*L300/170,I300*L300))) -> 292 | N300: ="₹/kg" -> ₹/kg | O300: ='yarn master raw '!K300 -> Ex-Mill + Freight | P300: ='yarn master raw '!L300 -> Yes | Q300: ='yarn master raw '!M300 -> Cotton Yarn Price Trend | R300: ='yarn master raw '!N300 -> Historical Price | S300: =IFERROR(IF(ISNUMBER(A300),YEAR(A300),IF(ISNUMBER(SEARCH("'",A300)),VALUE("20"&MID(A300,SEARCH("'",A300)+1,2)),IF(ISNUMBER(SEARCH("2023",A300)),2023,IF(ISNUMBER(SEARCH("2024",A300)),2024,IF(ISNUMBER(SEARCH("2025",A300)),2025,IF(ISNUMBER(SEARCH("2026",A300)),2026,2022)))))),"") -> 2026 | T300: March
